Workbook

Sheet YÜKLENİCİ ARAÇLARI
A1: FİRMA | B1: GÜZERGAH | C1: ŞAHIS | D1: PLAKA | E1: HAREKET | F1: GÜN TEK | G1: TUTAR | H1: TOPLAM | I1: 0,20% | J1: ARA TOP | K1: 0,10% | L1: G TOPLAM
A2: BAŞAK TRAKTÖR | B2: PATATES HALİ | C2: UFUK KÖYMEN | E2: GRŞ/ÇKŞ | F2: 19 | G2: 1800 | H2: =Tablo5[[#This Row],[GÜN TEK]]*Tablo5[[#This Row],[TUTAR]] -> 34200 | I2: =Tablo5[[#This Row],[TOPLAM]]*0.2 -> 6840 | J2: =SUM(Tablo5[[#This Row],[TOPLAM]:[0,20%]]) -> 41040 | K2: =Tablo5[[#This Row],[TOPLAM]]*0.1 -> 3420 | L2: =Tablo5[[#This Row],[TOPLAM]]+Tablo5[[#This Row],[0,20%]]-Tablo5[[#This Row],[0,10%]] -> 37620
A3: BAŞAK TRAKTÖR | B3: ŞEKER MAH MESAİ | C3: UFUK KÖYMEN | E3: MESAİ | H3: =Tablo5[[#This Row],[GÜN TEK]]*Tablo5[[#This Row],[TUTAR]] -> 0 | I3: =Tablo5[[#This Row],[TOPLAM]]*0.2 -> 0 | J3: =SUM(Tablo5[[#This Row],[TOPLAM]:[0,20%]]) -> 0 | K3: =Tablo5[[#This Row],[TOPLAM]]*0.1 -> 0 | L3: =Tablo5[[#This Row],[TOPLAM]]+Tablo5[[#This Row],[0,20%]]-Tablo5[[#This Row],[0,10%]] -> 0
A4: BAŞAK TRAKTÖR | B4: CENAZE İST | C4: UFUK KÖYMEN | E4: CENAZE | G4: 6500 | H4: =Tablo5[[#This Row],[GÜN TEK]]*Tablo5[[#This Row],[TUTAR]] -> 0 | I4: =Tablo5[[#This Row],[TOPLAM]]*0.2 -> 0 | J4: =SUM(Tablo5[[#This Row],[TOPLAM]:[0,20%]]) -> 0 | L4: =Tablo5[[#This Row],[TOPLAM]]+Tablo5[[#This Row],[0,20%]]-Tablo5[[#This Row],[0,10%]] -> 0
A5: BAŞAK TRAKTÖR | B5: KAZIMPAŞA ADATIP TEK | C5: SAFFET DİN (BÖLGEM TRZ) | E5: GRŞ/ÇKŞ | F5: 13 | G5: 2900 | H5: =Tablo5[[#This Row],[GÜN TEK]]*Tablo5[[#This Row],[TUTAR]] -> 37700 | I5: =Tablo5[[#This Row],[TOPLAM]]*0.2 -> 7540 | J5: =SUM(Tablo5[[#This Row],[TOPLAM]:[0,20%]]) -> 45240 | K5: =Tablo5[[#This Row],[TOPLAM]]*0.1 -> 3770 | L5: =Tablo5[[#This Row],[TOPLAM]]+Tablo5[[#This Row],[0,20%]]-Tablo5[[#This Row],[0,10%]] -> 41470
A6: BAŞAK TRAKTÖR | B6: BEŞEVLER ALANDÜZÜ | C6: YALÇIN DAMAR | E6: GRŞ/ÇKŞ | F6: 16 | G6: 2700 | H6: =Tablo5[[#This Row],[GÜN TEK]]*Tablo5[[#This Row],[TUTAR]] -> 43200 | I6: =Tablo5[[#This Row],[TOPLAM]]*0.2 -> 8640 | J6: =SUM(Tablo5[[#This Row],[TOPLAM]:[0,20%]]) -> 51840 | K6: =Tablo5[[#This Row],[TOPLAM]]*0.1 -> 4320 | L6: =Tablo5[[#This Row],[TOPLAM]]+Tablo5[[#This Row],[0,20%]]-Tablo5[[#This Row],[0,10%]] -> 47520
A7: BAŞAK TRAKTÖR | B7: BEŞEVLER ALANDÜZÜ MESAİ | C7: MEHMET ANLAŞ | E7: MESAİ | H7: =Tablo5[[#This Row],[GÜN TEK]]*Tablo5[[#This Row],[TUTAR]] -> 0 | I7: =Tablo5[[#This Row],[TOPLAM]]*0.2 -> 0 | J7: =SUM(Tablo5[[#This Row],[TOPLAM]:[0,20%]]) -> 0 | K7: =Tablo5[[#This Row],[TOPLAM]]*0.1 -> 0 | L7: =Tablo5[[#This Row],[TOPLAM]]+Tablo5[[#This Row],[0,20%]]-Tablo5[[#This Row],[0,10%]] -> 0
A8: BAŞAK TRAKTÖR | B8: 32 EVLER BEŞKÖPRÜ | C8: MEHMET ANLAŞ | E8: GRŞ/ÇKŞ | F8: 19 | G8: 1800 | H8: =Tablo5[[#This Row],[GÜN TEK]]*Tablo5[[#This Row],[TUTAR]] -> 34200 | I8: =Tablo5[[#This Row],[TOPLAM]]*0.2 -> 6840 | J8: =SUM(Tablo5[[#This Row],[TOPLAM]:[0,20%]]) -> 41040 | K8: =Tablo5[[#This Row],[TOPLAM]]*0.1 -> 3420 | L8: =Tablo5[[#This Row],[TOPLAM]]+Tablo5[[#This Row],[0,20%]]-Tablo5[[#This Row],[0,10%]] -> 37620
A9: BAŞAK TRAKTÖR | B9: SERDİVAN AVM 20:30 MESAİ | C9: MEHMET ANLAŞ | E9: MESAİ | F9: 1 | G9: =G8*2/3 -> 1200 | H9: =Tablo5[[#This Row],[GÜN TEK]]*Tablo5[[#This Row],[TUTAR]] -> 1200 | I9: =Tablo5[[#This Row],[TOPLAM]]*0.2 -> 240 | J9: =SUM(Tablo5[[#This Row],[TOPLAM]:[0,20%]]) -> 1440 | K9: =Tablo5[[#This Row],[TOPLAM]]*0.1 -> 120 | L9: =Tablo5[[#This Row],[TOPLAM]]+Tablo5[[#This Row],[0,20%]]-Tablo5[[#This Row],[0,10%]] -> 1320
A10: BAŞAK TRAKTÖR | B10: ŞEKER MAH MUHTARLIK | C10: SERKAN AKKOYUN | E10: GRŞ/ÇKŞ | F10: 13 | G10: 1800 | H10: =Tablo5[[#This Row],[GÜN TEK]]*Tablo5[[#This Row],[TUTAR]] -> 23400 | I10: =Tablo5[[#This Row],[TOPLAM]]*0.2 -> 4680 | J10: =SUM(Tablo5[[#This Row],[TOPLAM]:[0,20%]]) -> 28080 | K10: =Tablo5[[#This Row],[TOPLAM]]*0.1 -> 2340 | L10: =Tablo5[[#This Row],[TOPLAM]]+Tablo5[[#This Row],[0,20%]]-Tablo5[[#This Row],[0,10%]] -> 25740
A11: BAŞAK TRAKTÖR | B11: 20:30 MESAİ | C11: SERKAN AKKOYUN | E11: MESAİ | H11: =Tablo5[[#This Row],[GÜN TEK]]*Tablo5[[#This Row],[TUTAR]] -> 0 | I11: =Tablo5[[#This Row],[TOPLAM]]*0.2 -> 0 | J11: =SUM(Tablo5[[#This Row],[TOPLAM]:[0,20%]]) -> 0 | K11: =Tablo5[[#This Row],[TOPLAM]]*0.1 -> 0 | L11: =Tablo5[[#This Row],[TOPLAM]]+Tablo5[[#This Row],[0,20%]]-Tablo5[[#This Row],[0,10%]] -> 0
A12: BAŞAK TRAKTÖR | B12: Ş.FAB E.STAD.KENT PARK | C12: NEVZAT ÖZBAY | E12: GRŞ/ÇKŞ | F12: 13 | G12: 1800 | H12: =Tablo5[[#This Row],[GÜN TEK]]*Tablo5[[#This Row],[TUTAR]] -> 23400 | J12: =SUM(Tablo5[[#This Row],[TOPLAM]:[0,20%]]) -> 23400 | L12: =Tablo5[[#This Row],[TOPLAM]]+Tablo5[[#This Row],[0,20%]]-Tablo5[[#This Row],[0,10%]] -> 23400
A14: BAŞAK TRAKTÖR | B14: Ş.MAH İLAVE HACIOĞLU Ç.PZ | C14: VEYSEL KARATAŞ | E14: GRŞ/ÇKŞ | F14: 13 | G14: 1800 | H14: =Tablo5[[#This Row],[GÜN TEK]]*Tablo5[[#This Row],[TUTAR]] -> 23400 | I14: =Tablo5[[#This Row],[TOPLAM]]*0.2 -> 4680 | J14: =SUM(Tablo5[[#This Row],[TOPLAM]:[0,20%]]) -> 28080 | K14: =Tablo5[[#This Row],[TOPLAM]]*0.1 -> 2340 | L14: =Tablo5[[#This Row],[TOPLAM]]+Tablo5[[#This Row],[0,20%]]-Tablo5[[#This Row],[0,10%]] -> 25740
A15: BAŞAK TRAKTÖR | B15: ERNAZ YORGALAR MESAİ | C15: VEYSEL KARATAŞ | E15: MESAİ | H15: =Tablo5[[#This Row],[GÜN TEK]]*Tablo5[[#This Row],[TUTAR]] -> 0 | I15: =Tablo5[[#This Row],[TOPLAM]]*0.2 -> 0 | J15: =SUM(Tablo5[[#This Row],[TOPLAM]:[0,20%]]) -> 0 | K15: =Tablo5[[#This Row],[TOPLAM]]*0.1 -> 0 | L15: =Tablo5[[#This Row],[TOPLAM]]+Tablo5[[#This Row],[0,20%]]-Tablo5[[#This Row],[0,10%]] -> 0
A16: BAŞAK TRAKTÖR | B16: KURTKÖY SAPANCA | C16: MEHMET SERDAROĞLU | E16: GRŞ/ÇKŞ | F16: 19 | G16: 2750 | H16: =Tablo5[[#This Row],[GÜN TEK]]*Tablo5[[#This Row],[TUTAR]] -> 52250 | I16: =Tablo5[[#This Row],[TOPLAM]]*0.2 -> 10450 | J16: =SUM(Tablo5[[#This Row],[TOPLAM]:[0,20%]]) -> 62700 | K16: =Tablo5[[#This Row],[TOPLAM]]*0.1 -> 5225 | L16: =Tablo5[[#This Row],[TOPLAM]]+Tablo5[[#This Row],[0,20%]]-Tablo5[[#This Row],[0,10%]] -> 57475
A17: BAŞAK TRAKTÖR | B17: 20:30 MESAİ | C17: MEHMET SERDAROĞLU | E17: MESAİ | H17: =Tablo5[[#This Row],[GÜN TEK]]*Tablo5[[#This Row],[TUTAR]] -> 0 | I17: =Tablo5[[#This Row],[TOPLAM]]*0.2 -> 0 | J17: =SUM(Tablo5[[#This Row],[TOPLAM]:[0,20%]]) -> 0 | K17: =Tablo5[[#This Row],[TOPLAM]]*0.1 -> 0 | L17: =Tablo5[[#This Row],[TOPLAM]]+Tablo5[[#This Row],[0,20%]]-Tablo5[[#This Row],[0,10%]] -> 0
A18: BAŞAK TRAKTÖR | B18: ARİFİYE 1 MRK | C18: SALİH ÖZTAŞ | E18: GRŞ/ÇKŞ | F18: 18 | G18: 1800 | H18: =Tablo5[[#This Row],[GÜN TEK]]*Tablo5[[#This Row],[TUTAR]] -> 32400 | J18: =SUM(Tablo5[[#This Row],[TOPLAM]:[0,20%]]) -> 32400 | L18: =Tablo5[[#This Row],[TOPLAM]]+Tablo5[[#This Row],[0,20%]]-Tablo5[[#This Row],[0,10%]] -> 32400
A19: BAŞAK TRAKTÖR | B19: ESENCE 1- B.ESENCE | C19: ELİK TUR(HANİFİ ELİK) | E19: GRŞ/ÇKŞ | F19: 17 | G19: 2000 | H19: =Tablo5[[#This Row],[GÜN TEK]]*Tablo5[[#This Row],[TUTAR]] -> 34000 | I19: =Tablo5[[#This Row],[TOPLAM]]*0.2 -> 6800 | J19: =SUM(Tablo5[[#This Row],[TOPLAM]:[0,20%]]) -> 40800 | K19: =Tablo5[[#This Row],[TOPLAM]]*0.1 -> 3400 | L19: =Tablo5[[#This Row],[TOPLAM]]+Tablo5[[#This Row],[0,20%]]-Tablo5[[#This Row],[0,10%]] -> 37400
A20: BAŞAK TRAKTÖR | B20: 20:30 MESAİ | C20: ELİK TUR(HANİFİ ELİK) | E20: MESAİ | H20: =Tablo5[[#This Row],[GÜN TEK]]*Tablo5[[#This Row],[TUTAR]] -> 0 | I20: =Tablo5[[#This Row],[TOPLAM]]*0.2 -> 0 | J20: =SUM(Tablo5[[#This Row],[TOPLAM]:[0,20%]]) -> 0 | K20: =Tablo5[[#This Row],[TOPLAM]]*0.1 -> 0 | L20: =Tablo5[[#This Row],[TOPLAM]]+Tablo5[[#This Row],[0,20%]]-Tablo5[[#This Row],[0,10%]] -> 0
A21: BAŞAK TRAKTÖR | B21: ESENCE -2-//BEKİRPAŞA | C21: RAMİS GÜMÜŞ | E21: GRŞ/ÇKŞ | F21: 13 | G21: 2000 | H21: =Tablo5[[#This Row],[GÜN TEK]]*Tablo5[[#This Row],[TUTAR]] -> 26000 | I21: =Tablo5[[#This Row],[TOPLAM]]*0.2 -> 5200 | J21: =SUM(Tablo5[[#This Row],[TOPLAM]:[0,20%]]) -> 31200 | K21: =Tablo5[[#This Row],[TOPLAM]]*0.1 -> 2600 | L21: =Tablo5[[#This Row],[TOPLAM]]+Tablo5[[#This Row],[0,20%]]-Tablo5[[#This Row],[0,10%]] -> 28600
A22: BAŞAK TRAKTÖR | B22: ÇATALKÖPRÜ | C22: SERHAT TURAN TUR | E22: GRŞ/ÇKŞ | F22: 14 | G22: 2600 | H22: =Tablo5[[#This Row],[GÜN TEK]]*Tablo5[[#This Row],[TUTAR]] -> 36400 | I22: =Tablo5[[#This Row],[TOPLAM]]*0.2 -> 7280 | J22: =SUM(Tablo5[[#This Row],[TOPLAM]:[0,20%]]) -> 43680 | K22: =Tablo5[[#This Row],[TOPLAM]]*0.1 -> 3640 | L22: =Tablo5[[#This Row],[TOPLAM]]+Tablo5[[#This Row],[0,20%]]-Tablo5[[#This Row],[0,10%]] -> 40040
A23: BAŞAK TRAKTÖR | B23: GÜNEŞLER/OTTOMAN/Y.STAD | C23: RAMAZAN /MERVE YILMAZ | E23: GRŞ/ÇKŞ | F23: 13 | G23: 1800 | H23: =Tablo5[[#This Row],[GÜN TEK]]*Tablo5[[#This Row],[TUTAR]] -> 23400 | I23: =Tablo5[[#This Row],[TOPLAM]]*0.2 -> 4680 | J23: =SUM(Tablo5[[#This Row],[TOPLAM]:[0,20%]]) -> 28080 | K23: =Tablo5[[#This Row],[TOPLAM]]*0.1 -> 2340 | L23: =Tablo5[[#This Row],[TOPLAM]]+Tablo5[[#This Row],[0,20%]]-Tablo5[[#This Row],[0,10%]] -> 25740
A24: BAŞAK TRAKTÖR | B24: YENİCAMİ/SALKO CAMİİ | C24: UGUR ERGEZEN | E24: GRŞ/ÇKŞ | F24: 16.5 | G24: 1800 | H24: =Tablo5[[#This Row],[GÜN TEK]]*Tablo5[[#This Row],[TUTAR]] -> 29700 | I24: =Tablo5[[#This Row],[TOPLAM]]*0.2 -> 5940 | J24: =SUM(Tablo5[[#This Row],[TOPLAM]:[0,20%]]) -> 35640 | K24: =Tablo5[[#This Row],[TOPLAM]]*0.1 -> 2970 | L24: =Tablo5[[#This Row],[TOPLAM]]+Tablo5[[#This Row],[0,20%]]-Tablo5[[#This Row],[0,10%]] -> 32670
A25: BAŞAK TRAKTÖR | B25: YENİCAMİ MESAİ | C25: UGUR ERGEZEN | E25: MESAİ | H25: =Tablo5[[#This Row],[GÜN TEK]]*Tablo5[[#This Row],[TUTAR]] -> 0 | I25: =Tablo5[[#This Row],[TOPLAM]]*0.2 -> 0 | J25: =SUM(Tablo5[[#This Row],[TOPLAM]:[0,20%]]) -> 0 | K25: =Tablo5[[#This Row],[TOPLAM]]*0.1 -> 0 | L25: =Tablo5[[#This Row],[TOPLAM]]+Tablo5[[#This Row],[0,20%]]-Tablo5[[#This Row],[0,10%]] -> 0
A26: BAŞAK TRAKTÖR | B26: AKYAZI | C26: GÖKHAN IŞIK | E26: GRŞ/ÇKŞ | F26: 17 | G26: 2500 | H26: =Tablo5[[#This Row],[GÜN TEK]]*Tablo5[[#This Row],[TUTAR]] -> 42500 | I26: =Tablo5[[#This Row],[TOPLAM]]*0.2 -> 8500 | J26: =SUM(Tablo5[[#This Row],[TOPLAM]:[0,20%]]) -> 51000 | K26: =Tablo5[[#This Row],[TOPLAM]]*0.1 -> 4250 | L26: =Tablo5[[#This Row],[TOPLAM]]+Tablo5[[#This Row],[0,20%]]-Tablo5[[#This Row],[0,10%]] -> 46750
A27: BAŞAK TRAKTÖR | B27: AKYAZI MESAİ | C27: GÖKHAN IŞIK | E27: MESAİ | H27: =Tablo5[[#This Row],[GÜN TEK]]*Tablo5[[#This Row],[TUTAR]] -> 0 | I27: =Tablo5[[#This Row],[TOPLAM]]*0.2 -> 0 | J27: =SUM(Tablo5[[#This Row],[TOPLAM]:[0,20%]]) -> 0 | K27: =Tablo5[[#This Row],[TOPLAM]]*0.1 -> 0 | L27: =Tablo5[[#This Row],[TOPLAM]]+Tablo5[[#This Row],[0,20%]]-Tablo5[[#This Row],[0,10%]] -> 0
A28: BAŞAK TRAKTÖR | B28: YENİCAMİ/MRK/İŞ BANK | C28: SERHAT TURAN TUR | E28: GRŞ/ÇKŞ | G28: 1800 | H28: =Tablo5[[#This Row],[GÜN TEK]]*Tablo5[[#This Row],[TUTAR]] -> 0 | I28: =Tablo5[[#This Row],[TOPLAM]]*0.2 -> 0 | J28: =SUM(Tablo5[[#This Row],[TOPLAM]:[0,20%]]) -> 0 | K28: =Tablo5[[#This Row],[TOPLAM]]*0.1 -> 0 | L28: =Tablo5[[#This Row],[TOPLAM]]+Tablo5[[#This Row],[0,20%]]-Tablo5[[#This Row],[0,10%]] -> 0
A29: BAŞAK TRAKTÖR | B29: GÜNEŞLER/E.GRJ/E OKULU | C29: ERMAN TUR | E29: GRŞ/ÇKŞ | F29: 13 | G29: 1800 | H29: =Tablo5[[#This Row],[GÜN TEK]]*Tablo5[[#This Row],[TUTAR]] -> 23400 | I29: =Tablo5[[#This Row],[TOPLAM]]*0.2 -> 4680 | J29: =SUM(Tablo5[[#This Row],[TOPLAM]:[0,20%]]) -> 28080 | K29: =Tablo5[[#This Row],[TOPLAM]]*0.1 -> 2340 | L29: =Tablo5[[#This Row],[TOPLAM]]+Tablo5[[#This Row],[0,20%]]-Tablo5[[#This Row],[0,10%]] -> 25740
A30: BAŞAK TRAKTÖR | B30: MESAİ | C30: ERMAN TUR | E30: MESAİ | H30: =Tablo5[[#This Row],[GÜN TEK]]*Tablo5[[#This Row],[TUTAR]] -> 0 | I30: =Tablo5[[#This Row],[TOPLAM]]*0.2 -> 0 | J30: =SUM(Tablo5[[#This Row],[TOPLAM]:[0,20%]]) -> 0 | K30: =Tablo5[[#This Row],[TOPLAM]]*0.1 -> 0 | L30: =Tablo5[[#This Row],[TOPLAM]]+Tablo5[[#This Row],[0,20%]]-Tablo5[[#This Row],[0,10%]] -> 0
A31: BAŞAK TRAKTÖR | B31: FATİH E.MES.K.DİBİ TUZLA | C31: GÜVEN TUR | E31: GRŞ/ÇKŞ | F31: 13 | G31: 1800 | H31: =Tablo5[[#This Row],[GÜN TEK]]*Tablo5[[#This Row],[TUTAR]] -> 23400 | I31: =Tablo5[[#This Row],[TOPLAM]]*0.2 -> 4680 | J31: =SUM(Tablo5[[#This Row],[TOPLAM]:[0,20%]]) -> 28080 | K31: =Tablo5[[#This Row],[TOPLAM]]*0.1 -> 2340 | L31: =Tablo5[[#This Row],[TOPLAM]]+Tablo5[[#This Row],[0,20%]]-Tablo5[[#This Row],[0,10%]] -> 25740
A32: BAŞAK TRAKTÖR | B32: KARAMAN EVRENKÖY | C32: VEYSEL KARATAŞ | E32: GRŞ/ÇKŞ | F32: 10.5 | G32: 2300 | H32: =Tablo5[[#This Row],[GÜN TEK]]*Tablo5[[#This Row],[TUTAR]] -> 24150 | I32: =Tablo5[[#This Row],[TOPLAM]]*0.2 -> 4830 | J32: =SUM(Tablo5[[#This Row],[TOPLAM]:[0,20%]]) -> 28980 | K32: =Tablo5[[#This Row],[TOPLAM]]*0.1 -> 2415 | L32: =Tablo5[[#This Row],[TOPLAM]]+Tablo5[[#This Row],[0,20%]]-Tablo5[[#This Row],[0,10%]] -> 26565
A33: BAŞAK TRAKTÖR | B33: GÜLLÜK CAMİ/TEK | C33: KADİR TUNCEL | E33: GRŞ/ÇKŞ | F33: 13 | G33: 1800 | H33: =Tablo5[[#This Row],[GÜN TEK]]*Tablo5[[#This Row],[TUTAR]] -> 23400 | I33: =Tablo5[[#This Row],[TOPLAM]]*0.2 -> 4680 | J33: =SUM(Tablo5[[#This Row],[TOPLAM]:[0,20%]]) -> 28080 | K33: =Tablo5[[#This Row],[TOPLAM]]*0.1 -> 2340 | L33: =Tablo5[[#This Row],[TOPLAM]]+Tablo5[[#This Row],[0,20%]]-Tablo5[[#This Row],[0,10%]] -> 25740
A34: BAŞAK TRAKTÖR | B34: GEYVE | C34: İBRAHİM AKKUŞ | E34: GRŞ/ÇKŞ | F34: 17 | G34: 2900 | H34: =Tablo5[[#This Row],[GÜN TEK]]*Tablo5[[#This Row],[TUTAR]] -> 49300 | I34: =Tablo5[[#This Row],[TOPLAM]]*0.2 -> 9860 | J34: =SUM(Tablo5[[#This Row],[TOPLAM]:[0,20%]]) -> 59160 | K34: =Tablo5[[#This Row],[TOPLAM]]*0.1 -> 4930 | L34: =Tablo5[[#This Row],[TOPLAM]]+Tablo5[[#This Row],[0,20%]]-Tablo5[[#This Row],[0,10%]] -> 54230
A35: BAŞAK TRAKTÖR | B35: MESAİ | C35: İBRAHİM AKKUŞ | E35: MESAİ | H35: =Tablo5[[#This Row],[GÜN TEK]]*Tablo5[[#This Row],[TUTAR]] -> 0 | I35: =Tablo5[[#This Row],[TOPLAM]]*0.2 -> 0 | J35: =SUM(Tablo5[[#This Row],[TOPLAM]:[0,20%]]) -> 0 | K35: =Tablo5[[#This Row],[TOPLAM]]*0.1 -> 0 | L35: =Tablo5[[#This Row],[TOPLAM]]+Tablo5[[#This Row],[0,20%]]-Tablo5[[#This Row],[0,10%]] -> 0
A36: BAŞAK TRAKTÖR | B36: TÜRBE /HIZIRTEPE | C36: KADİR TUNCEL | E36: GRŞ/ÇKŞ | F36: 13 | G36: 1800 | H36: =Tablo5[[#This Row],[GÜN TEK]]*Tablo5[[#This Row],[TUTAR]] -> 23400 | I36: =Tablo5[[#This Row],[TOPLAM]]*0.2 -> 4680 | J36: =SUM(Tablo5[[#This Row],[TOPLAM]:[0,20%]]) -> 28080 | K36: =Tablo5[[#This Row],[TOPLAM]]*0.1 -> 2340 | L36: =Tablo5[[#This Row],[TOPLAM]]+Tablo5[[#This Row],[0,20%]]-Tablo5[[#This Row],[0,10%]] -> 25740
A37: BAŞAK TRAKTÖR | B37: DAĞDİBİ ÇEVRE YOLU | C37: EMİN-ARZU DİNDAROĞLU | E37: GRŞ/ÇKŞ | F37: 13 | G37: 1800 | H37: =Tablo5[[#This Row],[GÜN TEK]]*Tablo5[[#This Row],[TUTAR]] -> 23400 | I37: =Tablo5[[#This Row],[TOPLAM]]*0.2 -> 4680 | J37: =SUM(Tablo5[[#This Row],[TOPLAM]:[0,20%]]) -> 28080 | K37: =Tablo5[[#This Row],[TOPLAM]]*0.1 -> 2340 | L37: =Tablo5[[#This Row],[TOPLAM]]+Tablo5[[#This Row],[0,20%]]-Tablo5[[#This Row],[0,10%]] -> 25740
A38: BAŞAK TRAKTÖR | B38: ARİFİYE/AKÇAMLAR | C38: REMZİ/HÜRREM DORUK | E38: GRŞ/ÇKŞ | F38: 13 | G38: 1800 | H38: =Tablo5[[#This Row],[GÜN TEK]]*Tablo5[[#This Row],[TUTAR]] -> 23400 | J38: =SUM(Tablo5[[#This Row],[TOPLAM]:[0,20%]]) -> 23400 | L38: =Tablo5[[#This Row],[TOPLAM]]+Tablo5[[#This Row],[0,20%]]-Tablo5[[#This Row],[0,10%]] -> 23400
A39: BAŞAK TRAKTÖR | B39: AKYAZI/2 | C39: GÖKHAN IŞIK | E39: GRŞ/ÇKŞ | F39: 14 | G39: 2500 | H39: =Tablo5[[#This Row],[GÜN TEK]]*Tablo5[[#This Row],[TUTAR]] -> 35000 | I39: =Tablo5[[#This Row],[TOPLAM]]*0.2 -> 7000 | J39: =SUM(Tablo5[[#This Row],[TOPLAM]:[0,20%]]) -> 42000 | K39: =Tablo5[[#This Row],[TOPLAM]]*0.1 -> 3500 | L39: =Tablo5[[#This Row],[TOPLAM]]+Tablo5[[#This Row],[0,20%]]-Tablo5[[#This Row],[0,10%]] -> 38500
A40: BAŞAK TRAKTÖR | B40: ÇATALKÖPRÜ/AKYAZI MESAİ | C40: GÖKHAN IŞIK | E40: MESAİ | H40: =Tablo5[[#This Row],[GÜN TEK]]*Tablo5[[#This Row],[TUTAR]] -> 0 | I40: =Tablo5[[#This Row],[TOPLAM]]*0.2 -> 0 | J40: =SUM(Tablo5[[#This Row],[TOPLAM]:[0,20%]]) -> 0 | K40: =Tablo5[[#This Row],[TOPLAM]]*0.1 -> 0 | L40: =Tablo5[[#This Row],[TOPLAM]]+Tablo5[[#This Row],[0,20%]]-Tablo5[[#This Row],[0,10%]] -> 0
A41: BAŞAK TRAKTÖR | B41: KARAPÜRÇEK/EKİNLİ/ÇAYBAŞI | C41: RAMİS -HAKAN GÜMÜŞ | E41: GRŞ/ÇKŞ | F41: 17 | G41: 2650 | H41: =Tablo5[[#This Row],[GÜN TEK]]*Tablo5[[#This Row],[TUTAR]] -> 45050 | I41: =Tablo5[[#This Row],[TOPLAM]]*0.2 -> 9010 | J41: =SUM(Tablo5[[#This Row],[TOPLAM]:[0,20%]]) -> 54060 | K41: =Tablo5[[#This Row],[TOPLAM]]*0.1 -> 4505 | L41: =Tablo5[[#This Row],[TOPLAM]]+Tablo5[[#This Row],[0,20%]]-Tablo5[[#This Row],[0,10%]] -> 49555
...

Sheet ŞİRKET ARAÇ
A1: XXXXXX | B1: ŞAHIS | C1: PLAKA | D1: GİRİŞ/ÇIKIŞ | F1: TUTAR | G1: TOPLAM | H1: 0.2 | I1: ARA TOP | J1: 0.1 | K1: G TOPLAM
A2: OZANLAR | B2: ASİL TUR | C2: 54 S 0562 | D2: GRŞ/ÇIK | E2: 14 | F2: 3750 | G2: =E2*F2 -> 52500 | H2: =G2*0.2 -> 10500 | I2: =SUM(G2:H2) -> 63000 | J2: =H2/2 -> 5250 | K2: =G2+H2-J2 -> 57750
A3: SERDİVAN 1 | B3: ASİL TUR | C3: 54 S 1173 | D3: GRŞ/ÇIK | E3: 14 | F3: 3750 | G3: =E3*F3 -> 52500 | H3: =G3*0.2 -> 10500 | I3: =SUM(G3:H3) -> 63000 | J3: =H3/2 -> 5250 | K3: =G3+H3-J3 -> 57750
A4: KORUCUK 1 | B4: ASİL TUR | C4: 54 S 0857 | D4: GRŞ/ÇIK | E4: 18 | F4: 5100 | G4: =E4*F4 -> 91800 | H4: =G4*0.2 -> 18360 | J4: =H4/2 -> 9180 | K4: =G4+H4-J4 -> 100980
A5: KORUCUK EVRENKÖY | B5: ASİL TUR | C5: 54 S 0568 | D5: ÇIKIŞ | G5: =E5*F5 -> 0 | H5: =G5*0.2 -> 0 | J5: =H5/2 -> 0 | K5: =G5+H5-J5 -> 0
A6: KORUCUK | B6: ASİL TUR | C6: 54 S 2295 | D6: MESAİ | G6: =E6*F6 -> 0 | H6: =G6*0.2 -> 0 | J6: =H6/2 -> 0 | K6: =G6+H6-J6 -> 0
A7: KORUCUK YAZLIK | B7: ASİL TUR | C7: 54 S 0564 | D7: GRŞ/ÇIK | E7: 14 | F7: 5100 | G7: =E7*F7 -> 71400 | H7: =G7*0.2 -> 14280 | I7: =SUM(G7:H7) -> 85680 | J7: =H7/2 -> 7140 | K7: =G7+H7-J7 -> 78540
A8: KORUCUK YAZLIK | B8: ASİL TUR | C8: 54 S 0565 | D8: MESAİ | G8: =E8*F8 -> 0 | H8: =G8*0.2 -> 0 | I8: =SUM(G8:H8) -> 0 | J8: =H8/2 -> 0 | K8: =G8+H8-J8 -> 0
A9: CAMİLİ KARAMAN | B9: ASİL TUR | C9: 54 S 0565 | D9: GRŞ/ÇIK | E9: 13 | F9: 5100 | G9: =E9*F9 -> 66300 | H9: =G9*0.2 -> 13260 | I9: =SUM(G9:H9) -> 79560 | J9: =H9/2 -> 6630 | K9: =G9+H9-J9 -> 72930
A10: SERDİVAN MAVİ DURAK KAMP | B10: ASİL TUR | C10: 54 S 1194 | D10: GRŞ/ÇIK | E10: 13 | F10: 3750 | G10: =E10*F10 -> 48750 | H10: =G10*0.2 -> 9750 | I10: =SUM(G10:H10) -> 58500 | J10: =H10/2 -> 4875 | K10: =G10+H10-J10 -> 53625
A11: ŞEKER MAH MUHTARLIK | B11: ASİL TUR | C11: 54 S 0563 | D11: AKŞAM ÇIKIŞ | G11: =E11*F11 -> 0 | H11: =G11*0.2 -> 0 | I11: =SUM(G11:H11) -> 0 | J11: =H11/2 -> 0 | K11: =G11+H11-J11 -> 0
A12: ÇARŞI MESAİ | B12: ASİL TUR | C12: 54 S 0567 | D12: MESAİ | G12: =E12*F12 -> 0 | H12: =G12*0.2 -> 0 | I12: =SUM(G12:H12) -> 0 | J12: =H12/2 -> 0 | K12: =G12+H12-J12 -> 0
A13: ÇARŞI MESAİ | B13: ASİL TUR | C13: 54 S 0857 | D13: MESAİ | G13: =E13*F13 -> 0 | H13: =G13*0.2 -> 0 | I13: =SUM(G13:H13) -> 0 | J13: =H13/2 -> 0 | K13: =G13+H13-J13 -> 0
A14: ÇÖKEKLER BUDAKLAR GÜNEŞLER | B14: ASİL TUR | C14: 54 S 0257 | D14: GRŞ/ÇIK | E14: 13 | F14: 3800 | G14: =E14*F14 -> 49400 | H14: =G14*0.2 -> 9880 | I14: =SUM(G14:H14) -> 59280 | J14: =H14/2 -> 4940 | K14: =G14+H14-J14 -> 54340
A15: FERİZLİ SÖĞÜTLÜ | B15: ASİL TUR | C15: 54 S 0563 | D15: TEK | F15: 850 | G15: =E15*F15 -> 0 | H15: =G15*0.2 -> 0 | I15: =SUM(G15:H15) -> 0 | J15: =H15/2 -> 0 | K15: =G15+H15-J15 -> 0
A16: VARDİYE ÇARŞI | B16: ASİL TUR | C16: 54 S 3116 | D16: VRD | G16: =E16*F16 -> 0 | H16: =G16*0.2 -> 0 | I16: =SUM(G16:H16) -> 0 | J16: =H16/2 -> 0 | K16: =G16+H16-J16 -> 0
A17: VARDİYE ÇARŞI | B17: ASİL TUR | C17: 54 S 0856 | D17: VRD | F17: 850 | G17: =E17*F17 -> 0 | H17: =G17*0.2 -> 0 | I17: =SUM(G17:H17) -> 0 | J17: =H17/2 -> 0 | K17: =G17+H17-J17 -> 0
A18: aralık vrd | B18: ASİL TUR | C18: 54 S 858 | D18: VRD | F18: 1007 | G18: =E18*F18 -> 0 | H18: =G18*0.2 -> 0 | I18: =SUM(G18:H18) -> 0 | J18: =H18/2 -> 0 | K18: =G18+H18-J18 -> 0
A19: ÇÖKEKLER - 24 ÇIKIŞ | B19: ASİL TUR | C19: 54 S 0856 | D19: VRD | F19: 624.66 | G19: =E19*F19 -> 0 | H19: =G19*0.2 -> 0 | I19: =SUM(G19:H19) -> 0 | K19: =G19+H19-J19 -> 0
C20: 32000 | G20: =SUM(G2:G19) -> 432650 | H20: =SUM(H2:H19) -> 86530 | I20: =SUM(I2:I19) -> 409020 | J20: =SUM(J2:J19) -> 43265 | K20: =SUM(K2:K19) -> 475915
A23: ZZZZZZ | B23: ŞAHIS | C23: PLAKA | D23: GİRİŞ/ÇIKIŞ | F23: TUTAR | G23: TOPLAM | H23: 0.2 | I23: ARA TOP | J23: 0.1 | K23: G TOPLAM
A24: SAPANCA | B24: ASİL TUR | C24: 54 S 0562 | D24: GİRİŞ/ÇIKIŞ | E24: 19 | F24: 5000 | G24: =E24*F24 -> 95000 | H24: =G24*0.2 -> 19000 | I24: =SUM(G24:H24) -> 114000 | J24: =G24*J23 -> 9500 | K24: =G24+H24-J24 -> 104500
A25: SAPANCA | B25: ASİL TUR | C25: 54 S 0859 | D25: GİRİŞ/ÇIKIŞ | G25: =E25*F25 -> 0 | H25: =G25*0.2 -> 0 | I25: =SUM(G25:H25) -> 0 | J25: =G25*0.1 -> 0 | K25: =G25+H25-J25 -> 0
A26: ZZZZZZ | B26: ASİL TUR | C26: 54 S 0565 | D26: AKŞAM TEK | E26: 19 | F26: 821.25 | G26: =E26*F26 -> 15603.75 | H26: =G26*0.2 -> 3120.75 | I26: =SUM(G26:H26) -> 18724.5 | J26: =G26*0.1 -> 1560.375 | K26: =G26+H26-J26 -> 17164.125
A27: ZZZZZZ | B27: ASİL TUR | C27: 54 S 0564 | D27: TEK SABAH | E27: 19 | F27: 821.25 | G27: =E27*F27 -> 15603.75 | H27: =G27*0.2 -> 3120.75 | I27: =SUM(G27:H27) -> 18724.5 | J27: =G27*0.1 -> 1560.375 | K27: =G27+H27-J27 -> 17164.125
A28: ZZZZZZ | B28: ASİL TUR | C28: 54 S 567-2933 | D28: AKŞAM | E28: 19 | F28: 821.25 | G28: =E28*F28 -> 15603.75 | H28: =G28*0.2 -> 3120.75 | I28: =SUM(G28:H28) -> 18724.5 | J28: =G28*0.1 -> 1560.375 | K28: =G28+H28-J28 -> 17164.125
A29: ZZZZZZ | B29: ASİL TUR | C29: 54 S 0257 | D29: 1 SABAH+1 AKŞAM | E29: 38 | F29: 821.25 | G29: =E29*F29 -> 31207.5 | H29: =G29*0.2 -> 6241.5 | I29: =SUM(G29:H29) -> 37449 | J29: =G29*0.1 -> 3120.75 | K29: =G29+H29-J29 -> 34328.25
A30: ZZZZZZ | B30: ASİL TUR | C30: 54 S 3116 | D30: SABAH 2 TEK | E30: 0 | F30: 821.25 | G30: =E30*F30 -> 0 | H30: =G30*0.2 -> 0 | I30: =SUM(G30:H30) -> 0 | J30: =G30*0.1 -> 0 | K30: =G30+H30-J30 -> 0
A31: ZZZZZZ | B31: ASİL TUR | C31: 54 S 1773 | D31: 2 SABAH+1 AKŞAM | E31: 57 | F31: 821.25 | G31: =E31*F31 -> 46811.25 | H31: =G31*0.2 -> 9362.25 | I31: =SUM(G31:H31) -> 56173.5 | J31: =G31*0.1 -> 4681.125 | K31: =G31+H31-J31 -> 51492.375
A32: ZZZZZZ | B32: ASİL TUR | C32: 54 S 0857 | D32: AKŞAM TEK | E32: 19 | F32: 821.25 | G32: =E32*F32 -> 15603.75 | H32: =G32*0.2 -> 3120.75 | I32: =SUM(G32:H32) -> 18724.5 | J32: =G32*0.1 -> 1560.375 | K32: =G32+H32-J32 -> 17164.125
A33: ZZZZZZ | B33: ASİL TUR | C33: 54 S 1194 | D33: 2 SABAH+1 AKŞAM | E33: 57 | F33: 821.25 | G33: =E33*F33 -> 46811.25 | H33: =G33*0.2 -> 9362.25 | I33: =SUM(G33:H33) -> 56173.5 | J33: =G33*0.1 -> 4681.125 | K33: =G33+H33-J33 -> 51492.375
A34: ZZZZZZ | B34: ASİL TUR | C34: 54 S 0572 | D34: AKŞAM TEK | E34: 19 | F34: 821.25 | G34: =E34*F34 -> 15603.75 | H34: =G34*0.2 -> 3120.75 | I34: =SUM(G34:H34) -> 18724.5 | J34: =G34*0.1 -> 1560.375 | K34: =G34+H34-J34 -> 17164.125
A35: ZZZZZZ | C35: 54 S 2295 | D35: AKŞAM TEK | E35: 19 | F35: 821.25 | G35: =E35*F35 -> 15603.75 | H35: =G35*0.2 -> 3120.75 | I35: =SUM(G35:H35) -> 18724.5 | J35: =G35*0.1 -> 1560.375 | K35: =G35+H35-J35 -> 17164.125
C36: 54 S1773 | D36: AKŞAM TEK | G36: =E36*F36 -> 0 | H36: =G36*0.2 -> 0 | I36: =SUM(G36:H36) -> 0 | J36: =G36*0.1 -> 0 | K36: =G36+H36-J36 -> 0
D37: AKŞAM TEK | G37: =E37*F37 -> 0 | H37: =G37*0.2 -> 0 | I37: =SUM(G37:H37) -> 0 | J37: =G37*0.1 -> 0 | K37: =G37+H37-J37 -> 0
B38: MERKEZ | C38: =P23 -> 0 | D38: FİYAT FARK EFE | G38: =E38*F38 -> 0 | H38: =G38*0.2 -> 0 | I38: =SUM(G38:H38) -> 0 | J38: =G38*0.1 -> 0 | K38: =G38+H38-J38 -> 0
C39: 0.03397999 | D39: SAPANCA FİYAT FARK | G39: =E39*F39 -> 0 | H39: =G39*0.1 -> 0 | I39: =SUM(G39:H39) -> 0 | J39: =G39*0.1 -> 0 | K39: =G39+H39-J39 -> 0
G40: =SUM(G24:G38) -> 313452.5 | H40: =SUM(H24:H38) -> 62690.5 | I40: =SUM(I24:I38) -> 376143 | J40: =SUM(J24:J38) -> 31345.25 | K40: =SUM(K24:K38) -> 344797.75
A42: ZZZZZZZZ | B42: ŞAHIS | C42: PLAKA | D42: GİRİŞ/ÇIKIŞ | F42: TUTAR | G42: TOPLAM | H42: 0.2 | I42: ARA TOP | J42: 0.1 | K42: G TOPLAM
A43: ZZZZZZZZ | B43: VITO | C43: 54 TR 451 | D43: minibüs 8+1 | E43: 30 | F43: 2200 | G43: =E43*F43 -> 66000 | H43: =G43*0.2 -> 13200 | I43: =SUM(G43:H43) -> 79200 | J43: =G43*J42 -> 6600 | K43: =G43+J43 -> 72600
...

Sheet DAĞILIM
A1: =#REF! -> #REF!
A2: TAVSAN | B2: =#REF! -> #REF! | C2: =#REF! -> #REF! | E2: =#REF! -> #REF! | F2: =#REF! -> #REF! | G2: =#REF! -> #REF! | H2: =#REF! -> #REF! | I2: =#REF! -> #REF! | J2: =#REF! -> #REF! | K2: =#REF! -> #REF! | L2: =#REF! -> #REF!
A3: TANSAN | B3: =#REF! -> #REF! | C3: =#REF! -> #REF! | E3: =#REF! -> #REF! | F3: =#REF! -> #REF! | G3: =#REF! -> #REF! | H3: =#REF! -> #REF! | I3: =#REF! -> #REF! | J3: =#REF! -> #REF! | K3: =#REF! -> #REF! | L3: =#REF! -> #REF!
A4: EĞİTİM | B4: ABDURRAHMAN ONAT | E4: 1 ARAÇ | F4: =#REF! -> #REF! | G4: =#REF! -> #REF! | H4: =F4*G4 -> #REF! | I4: =H4*0.2 -> #REF! | J4: =SUM(H4:I4) -> #REF! | K4: =H4*0.1 -> #REF! | L4: =H4+K4 -> #REF!
H5: =SUM(H2:H4) -> #REF! | I5: =SUM(I2:I4) -> #REF! | J5: =SUM(J2:J4) -> #REF! | K5: =SUM(K2:K4) -> #REF! | L5: =SUM(L2:L4) -> #REF!
A6: ADİL YILMAZ
A7: ='YÜKLENİCİ ARAÇLARI'!A88 -> ALYAN GIDA | B7: ='YÜKLENİCİ ARAÇLARI'!B88 -> HENDEK MEMUR | C7: ='YÜKLENİCİ ARAÇLARI'!C88 -> ADİL YILMAZ | D7: ='YÜKLENİCİ ARAÇLARI'!D88 -> 54 S 0657 | E7: ='YÜKLENİCİ ARAÇLARI'!E88 -> TEK | F7: ='YÜKLENİCİ ARAÇLARI'!F88 -> 43 | G7: ='YÜKLENİCİ ARAÇLARI'!G88 -> 900 | H7: ='YÜKLENİCİ ARAÇLARI'!H88 -> 38700 | ... L7: ='YÜKLENİCİ ARAÇLARI'!L88 -> 42570
A8: ='YÜKLENİCİ ARAÇLARI'!A97 -> ALYAN GIDA | B8: ='YÜKLENİCİ ARAÇLARI'!B97 -> HENDEK YENİMAHALLE | C8: ='YÜKLENİCİ ARAÇLARI'!C97 -> ADİL YILMAZ SEFA ÖZPİLAVCI | D8: ='YÜKLENİCİ ARAÇLARI'!D97 -> 54 S 0798 | E8: ='YÜKLENİCİ ARAÇLARI'!E97 -> ÇİFT | F8: ='YÜKLENİCİ ARAÇLARI'!F97 -> 10 | G8: ='YÜKLENİCİ ARAÇLARI'!G97 -> 1100 | H8: ='YÜKLENİCİ ARAÇLARI'!H97 -> 11000 | ... L8: ='YÜKLENİCİ ARAÇLARI'!L97 -> 12100
A9: ='YÜKLENİCİ ARAÇLARI'!A98 -> ALYAN GIDA | B9: ='YÜKLENİCİ ARAÇLARI'!B98 -> HENDEK YENİMAHALLE | C9: ='YÜKLENİCİ ARAÇLARI'!C98 -> ADİL YILMAZ SEFA ÖZPİLAVCI | D9: ='YÜKLENİCİ ARAÇLARI'!D98 -> 54 S 0798 | E9: ='YÜKLENİCİ ARAÇLARI'!E98 -> TEK | F9: ='YÜKLENİCİ ARAÇLARI'!F98 -> 39 | G9: ='YÜKLENİCİ ARAÇLARI'!G98 -> 900 | H9: ='YÜKLENİCİ ARAÇLARI'!H98 -> 35100 | ... L9: ='YÜKLENİCİ ARAÇLARI'!L98 -> 38610
A10: ='YÜKLENİCİ ARAÇLARI'!A238 -> BURDA BEBEK | B10: ='YÜKLENİCİ ARAÇLARI'!B238 -> MUSTAFA ASIM | C10: ='YÜKLENİCİ ARAÇLARI'!C238 -> ADİL YILMAZ | D10: ='YÜKLENİCİ ARAÇLARI'!D238 -> 0 | E10: ='YÜKLENİCİ ARAÇLARI'!E238 -> GRŞ/ÇK/TEK | F10: ='YÜKLENİCİ ARAÇLARI'!F238 -> 30 | G10: ='YÜKLENİCİ ARAÇLARI'!G238 -> 900 | H10: ='YÜKLENİCİ ARAÇLARI'!H238 -> 27000 | ... L10: ='YÜKLENİCİ ARAÇLARI'!L238 -> 29700
A11: ='YÜKLENİCİ ARAÇLARI'!A95 -> ALYAN GIDA | B11: ='YÜKLENİCİ ARAÇLARI'!B95 -> HENDEK SU KENARI İLAVE | C11: ='YÜKLENİCİ ARAÇLARI'!C95 -> ADİL YILMAZ E.GÜNEYSU | D11: ='YÜKLENİCİ ARAÇLARI'!D95 -> 54 0881 | E11: ='YÜKLENİCİ ARAÇLARI'!E95 -> ÇİFT | F11: ='YÜKLENİCİ ARAÇLARI'!F95 -> 11 | G11: ='YÜKLENİCİ ARAÇLARI'!G95 -> 1250 | H11: ='YÜKLENİCİ ARAÇLARI'!H95 -> 13750 | ... L11: ='YÜKLENİCİ ARAÇLARI'!L95 -> 15125 | M11: 16 çift | N11: =SUM(L11:L12) -> 60170
A12: ='YÜKLENİCİ ARAÇLARI'!A96 -> ALYAN GIDA | B12: ='YÜKLENİCİ ARAÇLARI'!B96 -> HENDEK SU KENARI İLAVE | C12: ='YÜKLENİCİ ARAÇLARI'!C96 -> ADİL YILMAZ E.GÜNEYSU | D12: ='YÜKLENİCİ ARAÇLARI'!D96 -> 54 0881 | E12: ='YÜKLENİCİ ARAÇLARI'!E96 -> TEK | F12: ='YÜKLENİCİ ARAÇLARI'!F96 -> 42 | G12: ='YÜKLENİCİ ARAÇLARI'!G96 -> 975 | H12: ='YÜKLENİCİ ARAÇLARI'!H96 -> 40950 | ... L12: ='YÜKLENİCİ ARAÇLARI'!L96 -> 45045 | M12: 32 tek | N12: 51200
A13: ='YÜKLENİCİ ARAÇLARI'!A290 -> ISILSAN | B13: ='YÜKLENİCİ ARAÇLARI'!B290 -> HENDEK KÖY YEŞİLYURT/YAĞBASAN | C13: ='YÜKLENİCİ ARAÇLARI'!C290 -> ADİL YILMAZ/M ÇİLEK | D13: ='YÜKLENİCİ ARAÇLARI'!D290 -> 55 S 0210 | E13: ='YÜKLENİCİ ARAÇLARI'!E290 -> VRD | F13: ='YÜKLENİCİ ARAÇLARI'!F290 -> 38.5 | G13: ='YÜKLENİCİ ARAÇLARI'!G290 -> 2000 | H13: ='YÜKLENİCİ ARAÇLARI'!H290 -> 77000 | ... L13: ='YÜKLENİCİ ARAÇLARI'!L290 -> 84700 | N13: =N11-N12 -> 8970
A14: ='YÜKLENİCİ ARAÇLARI'!A291 -> ISILSAN | B14: ='YÜKLENİCİ ARAÇLARI'!B291 -> HENDEK KÖY YEŞİLYURT/YAĞBASAN | C14: ='YÜKLENİCİ ARAÇLARI'!C291 -> ADİL YILMAZ/M ÇİLEK | D14: ='YÜKLENİCİ ARAÇLARI'!D291 -> 56 S 0210 | E14: ='YÜKLENİCİ ARAÇLARI'!E291 -> MRK/MES | F14: ='YÜKLENİCİ ARAÇLARI'!F291 -> 7 | G14: ='YÜKLENİCİ ARAÇLARI'!G291 -> 1160 | H14: ='YÜKLENİCİ ARAÇLARI'!H291 -> 8120 | ... L14: ='YÜKLENİCİ ARAÇLARI'!L291 -> 8932
A15: ='YÜKLENİCİ ARAÇLARI'!A292 -> ISILSAN | B15: ='YÜKLENİCİ ARAÇLARI'!B292 -> HENDEK KÖY YEŞİLYURT/YAĞBASAN | C15: ='YÜKLENİCİ ARAÇLARI'!C292 -> ADİL YILMAZ/M ÇİLEK | D15: ='YÜKLENİCİ ARAÇLARI'!D292 -> 57 S 0210 | E15: ='YÜKLENİCİ ARAÇLARI'!E292 -> KÖY/MESAİ | F15: ='YÜKLENİCİ ARAÇLARI'!F292 -> 4 | G15: ='YÜKLENİCİ ARAÇLARI'!G292 -> 1300 | H15: ='YÜKLENİCİ ARAÇLARI'!H292 -> 5200 | ... L15: ='YÜKLENİCİ ARAÇLARI'!L292 -> 5720
A16: ='YÜKLENİCİ ARAÇLARI'!A293 -> ISILSAN | B16: ='YÜKLENİCİ ARAÇLARI'!B293 -> CUMA | C16: ='YÜKLENİCİ ARAÇLARI'!C293 -> ADİL YILMAZ/M ÇİLEK | D16: ='YÜKLENİCİ ARAÇLARI'!D293 -> 58 S 0210 | E16: ='YÜKLENİCİ ARAÇLARI'!E293 -> CUMA | F16: ='YÜKLENİCİ ARAÇLARI'!F293 -> 3 | G16: ='YÜKLENİCİ ARAÇLARI'!G293 -> 900 | H16: ='YÜKLENİCİ ARAÇLARI'!H293 -> 2700 | ... L16: ='YÜKLENİCİ ARAÇLARI'!L293 -> 2970
A17: ='YÜKLENİCİ ARAÇLARI'!A222 -> TAVSAN | B17: ='YÜKLENİCİ ARAÇLARI'!B222 -> HENDEK 4 İLAVE | C17: ='YÜKLENİCİ ARAÇLARI'!C222 -> ADİL YILMAZ | D17: ='YÜKLENİCİ ARAÇLARI'!D222 -> 0 | E17: ='YÜKLENİCİ ARAÇLARI'!E222 -> GRŞ/ÇIKIŞ | F17: ='YÜKLENİCİ ARAÇLARI'!F222 -> 18 | G17: ='YÜKLENİCİ ARAÇLARI'!G222 -> 1800 | H17: ='YÜKLENİCİ ARAÇLARI'!H222 -> 32400 | ... L17: ='YÜKLENİCİ ARAÇLARI'!L222 -> 35640
H18: =SUM(H7:H17) -> 291920 | I18: =SUM(I7:I17) -> 58384 | J18: =SUM(J7:J17) -> 350304 | K18: =SUM(K7:K17) -> 29192 | L18: =SUM(L7:L17) -> 321112
A20: AHMET (ÖMER LÜTFÜ)ATABEK
A21: ='YÜKLENİCİ ARAÇLARI'!A82 -> ALYAN GIDA | B21: ='YÜKLENİCİ ARAÇLARI'!B82 -> HENDEK SARIDEDE Y OSM B.T | C21: ='YÜKLENİCİ ARAÇLARI'!C82 -> AHMET ATABEK | D21: ='YÜKLENİCİ ARAÇLARI'!D82 -> 54 S 1187 | E21: ='YÜKLENİCİ ARAÇLARI'!E82 -> ÇİFT | F21: ='YÜKLENİCİ ARAÇLARI'!F82 -> 41 | G21: ='YÜKLENİCİ ARAÇLARI'!G82 -> 1100 | H21: ='YÜKLENİCİ ARAÇLARI'!H82 -> 45100 | ... L21: ='YÜKLENİCİ ARAÇLARI'!L82 -> 49610
A22: ='YÜKLENİCİ ARAÇLARI'!A83 -> ALYAN GIDA | B22: ='YÜKLENİCİ ARAÇLARI'!B83 -> HENDEK SARIDEDE Y OSM B.T | C22: ='YÜKLENİCİ ARAÇLARI'!C83 -> AHMET ATABEK | D22: ='YÜKLENİCİ ARAÇLARI'!D83 -> 54 S 1187 | E22: ='YÜKLENİCİ ARAÇLARI'!E83 -> TEK | F22: ='YÜKLENİCİ ARAÇLARI'!F83 -> 11 | G22: ='YÜKLENİCİ ARAÇLARI'!G83 -> 900 | H22: ='YÜKLENİCİ ARAÇLARI'!H83 -> 9900 | ... L22: ='YÜKLENİCİ ARAÇLARI'!L83 -> 10890
H23: =SUM(H21:H22) -> 55000 | I23: =SUM(I21:I22) -> 11000 | J23: =SUM(J21:J22) -> 66000 | K23: =SUM(K21:K22) -> 5500 | L23: =SUM(L21:L22) -> 60500
A24: AHMET CAN KAHVECİ
A25: ='YÜKLENİCİ ARAÇLARI'!A217 -> TAVSAN | B25: ='YÜKLENİCİ ARAÇLARI'!B217 -> HENDEK 2 | C25: ='YÜKLENİCİ ARAÇLARI'!C217 -> AHMET CAN KAHVECİ | D25: ='YÜKLENİCİ ARAÇLARI'!D217 -> 0 | E25: ='YÜKLENİCİ ARAÇLARI'!E217 -> GRŞ/ÇIKIŞ | F25: ='YÜKLENİCİ ARAÇLARI'!F216 -> 18 | G25: ='YÜKLENİCİ ARAÇLARI'!G217 -> 1800 | H25: ='YÜKLENİCİ ARAÇLARI'!H217 -> 45000 | I25: ='YÜKLENİCİ ARAÇLARI'!I217 -> 9000 | J25: ='YÜKLENİCİ ARAÇLARI'!J217 -> 54000 | K25: ='YÜKLENİCİ ARAÇLARI'!K217 -> 4500 | L25: ='YÜKLENİCİ ARAÇLARI'!L217 -> 49500
A26: =#REF! -> #REF! | B26: =#REF! -> #REF! | C26: =#REF! -> #REF! | E26: =#REF! -> #REF! | F26: =#REF! -> #REF! | G26: =#REF! -> #REF! | H26: =F26*G26 -> #REF! | I26: =H26*0.2 -> #REF! | J26: =SUM(H26:I26) -> #REF! | K26: =H26*0.1 -> #REF! | L26: =H26+K26 -> #REF!
A27: 1//HENDEK | B27: AHMET CAN KAHVECİ | C27: EKİM AYINDAN 3 TEK | E27: GİRİŞ/ÇIKIŞ | G27: 400 | H27: =F27*G27 -> 0 | I27: =H27*0.2 -> 0 | J27: =SUM(H27:I27) -> 0 | K27: =H27*0.1 -> 0 | L27: =H27+K27 -> 0
H28: =SUM(H25) -> 45000 | I28: =SUM(I25) -> 9000 | J28: =SUM(J25) -> 54000 | K28: =SUM(K25) -> 4500 | L28: =SUM(L25) -> 49500
A29: ALİ BAHRİ DEMİR
A30: ='YÜKLENİCİ ARAÇLARI'!A63 -> TÜRESAŞ | B30: ='YÜKLENİCİ ARAÇLARI'!B63 -> GEYVE | C30: ='YÜKLENİCİ ARAÇLARI'!C63 -> ALİ BAHRİ DEMİR | E30: ='YÜKLENİCİ ARAÇLARI'!E63 -> GRŞ/ÇKŞ | F30: ='YÜKLENİCİ ARAÇLARI'!F63 -> 19 | G30: ='YÜKLENİCİ ARAÇLARI'!G63 -> 3750 | H30: ='YÜKLENİCİ ARAÇLARI'!H63 -> 71250 | I30: ='YÜKLENİCİ ARAÇLARI'!I63 -> 14250 | J30: ='YÜKLENİCİ ARAÇLARI'!J63 -> 85500 | K30: ='YÜKLENİCİ ARAÇLARI'!K63 -> 7125 | L30: ='YÜKLENİCİ ARAÇLARI'!L63 -> 78375
H31: =SUM(H30:H30) -> 71250 | I31: =SUM(I30:I30) -> 14250 | J31: =SUM(J30:J30) -> 85500 | K31: =SUM(K30:K30) -> 7125 | L31: =SUM(L30:L30) -> 78375
A32: ALİCAN BAŞER
A33: ='YÜKLENİCİ ARAÇLARI'!A165 -> GEDİK KAYNAK | B33: ='YÜKLENİCİ ARAÇLARI'!B165 -> KAYNARCA SU KEN.SİVRİ TEPE | C33: ='YÜKLENİCİ ARAÇLARI'!C165 -> ALİCAN BAŞER | D33: ='YÜKLENİCİ ARAÇLARI'!D165 -> 0 | E33: ='YÜKLENİCİ ARAÇLARI'!E165 -> VRD | F33: ='YÜKLENİCİ ARAÇLARI'!F165 -> 14 | G33: ='YÜKLENİCİ ARAÇLARI'!G165 -> 700 | H33: ='YÜKLENİCİ ARAÇLARI'!H165 -> 9800 | ... L33: ='YÜKLENİCİ ARAÇLARI'!L165 -> 10780
A34: ='YÜKLENİCİ ARAÇLARI'!A166 -> GEDİK KAYNAK | B34: ='YÜKLENİCİ ARAÇLARI'!B166 -> KAYNARCA SU KEN.SİVRİ TEPE | C34: ='YÜKLENİCİ ARAÇLARI'!C166 -> ALİCAN BAŞER | D34: ='YÜKLENİCİ ARAÇLARI'!D166 -> 0 | E34: ='YÜKLENİCİ ARAÇLARI'!E166 -> TEK YÖN G/Ç | F34: ='YÜKLENİCİ ARAÇLARI'!F166 -> 42 | G34: ='YÜKLENİCİ ARAÇLARI'!G166 -> 1250 | H34: ='YÜKLENİCİ ARAÇLARI'!H166 -> 52500 | ... L34: ='YÜKLENİCİ ARAÇLARI'!L166 -> 57750
H35: =SUM(H33:H34) -> 62300 | I35: =SUM(I33:I34) -> 12460 | J35: =SUM(J33:J34) -> 74760 | K35: =SUM(K33:K34) -> 6230 | L35: =SUM(L33:L34) -> 68530
H38: =SUM(H37) -> 0 | I38: =SUM(I37) -> 0 | J38: =SUM(J37) -> 0 | K38: =SUM(K37) -> 0 | L38: =SUM(L37) -> 0
A40: ARDA ÖZKÖK FUAT YÜCE
A41: =#REF! -> #REF! | B41: =#REF! -> #REF! | C41: =#REF! -> #REF! | E41: =#REF! -> #REF! | F41: =#REF! -> #REF! | G41: =#REF! -> #REF! | H41: =#REF! -> #REF! | I41: =#REF! -> #REF! | J41: =#REF! -> #REF! | K41: =#REF! -> #REF! | L41: =#REF! -> #REF!
A42: ='YÜKLENİCİ ARAÇLARI'!A275 -> AQUAKRAFT | B42: ='YÜKLENİCİ ARAÇLARI'!B275 -> ADAPAZARI/MERKEZ /ERENLER | C42: ='YÜKLENİCİ ARAÇLARI'!C275 -> FUAT YÜCE | D42: ='YÜKLENİCİ ARAÇLARI'!D275 -> 0 | E42: ='YÜKLENİCİ ARAÇLARI'!E275 -> GRŞ/ÇIK | F42: ='YÜKLENİCİ ARAÇLARI'!F275 -> 0 | G42: ='YÜKLENİCİ ARAÇLARI'!G275 -> 2000 | H42: ='YÜKLENİCİ ARAÇLARI'!H275 -> 0 | ... L42: ='YÜKLENİCİ ARAÇLARI'!L275 -> 0
A43: ='YÜKLENİCİ ARAÇLARI'!A276 -> AQUAKRAFT | B43: ='YÜKLENİCİ ARAÇLARI'!B276 -> ADAPAZARI/MERKEZ /ERENLER | C43: ='YÜKLENİCİ ARAÇLARI'!C276 -> FUAT YÜCE | D43: ='YÜKLENİCİ ARAÇLARI'!D276 -> 0 | E43: ='YÜKLENİCİ ARAÇLARI'!E276 -> TEK | F43: ='YÜKLENİCİ ARAÇLARI'!F276 -> 52 | G43: ='YÜKLENİCİ ARAÇLARI'!G276 -> 1500 | H43: ='YÜKLENİCİ ARAÇLARI'!H276 -> 78000 | ... L43: ='YÜKLENİCİ ARAÇLARI'!L276 -> 85800
H44: =SUM(H42:H43) -> 78000 | I44: =SUM(I42:I43) -> 15600 | J44: =SUM(J42:J43) -> 93600 | K44: =SUM(K42:K43) -> 7800 | L44: =SUM(L42:L43) -> 85800
...

Sheet ÖDEME  TOPLAM
A1: HAZİRAN 2025 ÇALIŞAN HAKEDİŞ | B1: TOPLAM HAKEDİŞ | C1: MAZOT | D1: borç kesinti | E1: AVANS | F1: AVANS | G1: BANKADAN ÖDEME | H1: BANKADAN ÖDEME | I1: BANKADAN ÖDEME | J1: BANKADAN ÖDEME | K1: BANKADAN ÖDEME 1 | L1: ÖDEME 2 | M1: ÖDEME 3 | N1: KALAN
A2: =DAĞILIM!A1 -> #REF! | B2: =DAĞILIM!L5 -> #REF! | N2: =B2-C2-D2-E2-F2-G2-J2-#REF!-K2-L2-#REF! -> #REF!
A3: =DAĞILIM!A6 -> ADİL YILMAZ | B3: =DAĞILIM!L18 -> 321112 | K3: 321112 | N3: =B3-C3-D3-E3-F3-G3-H3-I3-J3-K3-L3-M3 -> 0
A4: =DAĞILIM!A20 -> AHMET (ÖMER LÜTFÜ)ATABEK | B4: =DAĞILIM!L23 -> 60500 | C4: 3592.032 | K4: 56907.97 | N4: =B4-C4-D4-E4-F4-G4-H4-I4-J4-K4-L4-M4 -> -0.002
A5: =DAĞILIM!A24 -> AHMET CAN KAHVECİ | B5: =DAĞILIM!L28 -> 49500 | K5: 49500 | N5: =B5-C5-D5-E5-F5-G5-H5-I5-J5-K5-L5-M5 -> 0
A6: =DAĞILIM!A29 -> ALİ BAHRİ DEMİR | B6: =DAĞILIM!L31 -> 78375 | K6: 78375 | N6: =B6-C6-D6-E6-F6-G6-H6-I6-J6-K6-L6-M6 -> 0
A7: =DAĞILIM!A32 -> ALİCAN BAŞER | B7: =DAĞILIM!L35 -> 68530 | K7: 68530 | N7: =B7-C7-D7-E7-F7-G7-H7-I7-J7-K7-L7-M7 -> 0
A8: =DAĞILIM!A40 -> ARDA ÖZKÖK FUAT YÜCE | B8: =DAĞILIM!L44 -> 85800 | E8: 85800 | N8: =B8-C8-D8-E8-F8-G8-H8-I8-J8-K8-L8-M8 -> 0
A9: =DAĞILIM!A46 -> EROL ÖZTÜFEKÇİ | B9: =DAĞILIM!L48 -> 46200 | K9: 46200 | N9: =B9-C9-D9-E9-F9-G9-H9-I9-J9-K9-L9-M9 -> 0
A10: =DAĞILIM!A49 -> BARIŞ(RIDVAN)İSLAM | B10: =DAĞILIM!L52 -> 41580 | K10: 41580 | N10: =B10-C10-D10-E10-F10-G10-H10-I10-J10-K10-L10-M10 -> 0
A11: =DAĞILIM!A53 -> BAYRAM YILMAZ | B11: =DAĞILIM!L64 -> 267091 | C11: 16164.144 | D11: 7500 | K11: 243426.86 | N11: =B11-C11-D11-E11-F11-G11-H11-I11-J11-K11-L11-M11 -> -0.004
A12: =DAĞILIM!A65 -> BAYRAM YILMAZ | B12: =DAĞILIM!L68 -> 66990 | C12: 2694.024 | K12: 64295.98 | N12: =B12-C12-D12-E12-F12-G12-H12-I12-J12-K12-L12-M12 -> -0.004
A13: =DAĞILIM!A69 -> BARIŞ YILMAZ | B13: =DAĞILIM!L75 -> 45155 | K13: 45155 | N13: =B13-C13-D13-E13-F13-G13-H13-I13-J13-K13-L13-M13 -> 0
A14: =DAĞILIM!A77 -> CEVDET KARAGÜZEL | B14: =DAĞILIM!L80 -> 47520 | K14: 47520 | N14: =B14-C14-D14-E14-F14-G14-H14-I14-J14-K14-L14-M14 -> 0
A15: =DAĞILIM!A81 -> HAMDİ ÖCAL SAPANCA SEYAHAT | B15: =DAĞILIM!L83 -> 73150 | K15: 73150 | N15: =B15-C15-D15-E15-F15-G15-H15-I15-J15-K15-L15-M15 -> 0
A16: =DAĞILIM!A85 -> HASAN KAPDAN | B16: =DAĞILIM!L89 -> 114878.5 | K16: 114878.5 | N16: =B16-C16-D16-E16-F16-G16-H16-I16-J16-K16-L16-M16 -> 0
A17: =DAĞILIM!A90 -> ELİK TUR HANİFE ELİK | B17: =DAĞILIM!L93 -> 37400 | K17: 37400 | N17: =B17-C17-D17-E17-F17-G17-H17-I17-J17-K17-L17-M17 -> 0
A18: =DAĞILIM!A94 -> EMİRCAN ÖZCAN KURT | B18: =DAĞILIM!L107 -> 241440 | C18: ='[2]DIŞ ALIM'!$H$65 -> 65341.252 | D18: 1500 | E18: ='[3]2-3-8'!$E$22 -> 150000 | F18: 115000 | J18: 67000 | K18: 65000 | N18: =B18-C18-D18-E18-F18-G18-H18-I18-J18-K18-L18-M18 -> -222401.25
A19: =DAĞILIM!A109 -> YUNUS EMRE OCAK | B19: =DAĞILIM!L115 -> 110605 | C19: =SUM('[2]DIŞ ALIM'!$H$79) -> 5416.1705 | K19: 105188.83 | N19: =B19-C19-D19-E19-F19-G19-H19-I19-J19-K19-L19-M19 -> -0.00045599999
A20: =DAĞILIM!A117 -> ENES YILMAZ HASAN AKDAĞCI | B20: =DAĞILIM!L120 -> 64680 | C20: =SUM('[2]DIŞ ALIM'!$H$74) -> 2604.2232 | K20: 62075.78 | N20: =B20-C20-D20-E20-F20-G20-H20-I20-J20-K20-L20-M20 -> -0.0032
A21: =DAĞILIM!A121 -> ERMAN TUR İBRAHİM ERMAN | B21: =DAĞILIM!L124 -> 25740 | K21: 25740 | N21: =B21-C21-D21-E21-F21-G21-H21-I21-J21-K21-L21-M21 -> 0
A22: =DAĞILIM!A125 -> FEYYAZ POLUMCU | B22: =DAĞILIM!L127 -> 55440 | K22: 55440 | N22: =B22-C22-D22-E22-F22-G22-H22-I22-J22-K22-L22-M22 -> 0
A23: =DAĞILIM!A128 -> dursun YILMAZ ÖRCÜN | B23: =DAĞILIM!L131 -> 63096 | C23: 15266.136 | K23: 47829.86 | N23: =B23-C23-D23-E23-F23-G23-H23-I23-J23-K23-L23-M23 -> 0.004
A24: =DAĞILIM!A132 -> EYÜP ERDİ TÜREDİ | B24: =DAĞILIM!L137 -> 149985 | K24: 149985 | N24: =B24-C24-D24-E24-F24-G24-H24-I24-J24-K24-L24-M24 -> 0
A25: =DAĞILIM!C140 -> EMEL ÖMER ÖNENÇ(otur butur) | B25: =DAĞILIM!L142 -> 79200 | D25: ='[3]01 TEMMUZ DEVAM'!$E$4 -> 11538.95 | K25: 67661.05 | N25: =B25-C25-D25-E25-F25-G25-H25-I25-J25-K25-L25-M25 -> 0
A26: =DAĞILIM!A149 -> FEHİM YALÇINKAYA | B26: =DAĞILIM!L161 -> 401390 | K26: 401390 | N26: =B26-C26-D26-E26-F26-G26-H26-I26-J26-K26-L26-M26 -> 0
A27: =DAĞILIM!A163 -> FETİH AKTAŞ | B27: =DAĞILIM!L165 -> 59400 | E27: 59400 | N27: =B27-C27-D27-E27-F27-G27-H27-I27-J27-K27-L27-M27 -> 0
A28: =DAĞILIM!A167 -> OSMAN GÖKHAN IŞIK | B28: =DAĞILIM!L188 -> 664405.5 | E28: 100000 | J28: 64405 | K28: 500000 | N28: =B28-C28-D28-E28-F28-G28-H28-I28-J28-K28-L28-M28 -> 0.5
A29: =DAĞILIM!A191 -> GÜVEN TUR | B29: =DAĞILIM!L193 -> 25740 | K29: 25740 | N29: =B29-C29-D29-E29-F29-G29-H29-I29-J29-K29-L29-M29 -> 0
A30: =DAĞILIM!A194 -> ÖMER DER | B30: =DAĞILIM!L198 -> 55440 | K30: 55440 | N30: =B30-C30-D30-E30-F30-G30-H30-I30-J30-K30-L30-M30 -> 0
A31: =DAĞILIM!A199 -> HALİL BÜYÜKTANZİM | B31: =DAĞILIM!L202 -> 73700 | K31: 73700 | N31: =B31-C31-D31-E31-F31-G31-H31-I31-J31-K31-L31-M31 -> 0
A32: =DAĞILIM!A203 -> HALİL BÜYÜKTANZİM | B32: =DAĞILIM!L206 -> 35640 | K32: 35640 | N32: =B32-C32-D32-E32-F32-G32-H32-I32-J32-K32-L32-M32 -> 0
A33: =DAĞILIM!A207 -> İBRAHİM OKUMUŞ | B33: =DAĞILIM!L210 -> 85140 | K33: 85140 | N33: =B33-C33-D33-E33-F33-G33-H33-I33-J33-K33-L33-M33 -> 0
A34: =DAĞILIM!A213 -> REMZİ HÜRREM DORUK | B34: =DAĞILIM!L215 -> 23400 | K34: 23400 | N34: =B34-C34-D34-E34-F34-G34-H34-I34-J34-K34-L34-M34 -> 0
A35: =DAĞILIM!A216 -> GÖKHAN İBRAHİM AKKUŞ | B35: =DAĞILIM!L219 -> 54230 | K35: 54230 | N35: =B35-C35-D35-E35-F35-G35-H35-I35-J35-K35-L35-M35 -> 0
A36: =DAĞILIM!A220 -> İBRAHİM DER | B36: =DAĞILIM!L222 -> 47520 | K36: 47520 | N36: =B36-C36-D36-E36-F36-G36-H36-I36-J36-K36-L36-M36 -> 0
A37: =DAĞILIM!A223 -> İSMAİL AÇIKDENİZ | B37: =DAĞILIM!L228 -> 112860 | K37: 112860 | N37: =B37-C37-D37-E37-F37-G37-H37-I37-J37-K37-L37-M37 -> 0
A38: =DAĞILIM!A229 -> KADİR TUNCEL TUNCEL TRZ | B38: =DAĞILIM!L234 -> 87120 | K38: 87120 | N38: =B38-C38-D38-E38-F38-G38-H38-I38-J38-K38-L38-M38 -> 0
A39: =DAĞILIM!A235 -> MEHMET ANLAŞ | B39: =DAĞILIM!L241 -> 177870 | D39: ='[3]2-3-8'!$E$21 -> 100000 | E39: 25000 | K39: 52870 | N39: =B39-C39-D39-E39-F39-G39-H39-I39-J39-K39-L39-M39 -> 0
A40: =DAĞILIM!A242 -> MEHMET ELLİİKİ | B40: =DAĞILIM!L245 -> 26100 | K40: 26100 | N40: =B40-C40-D40-E40-F40-G40-H40-I40-J40-K40-L40-M40 -> 0
...

Sheet FATURALANDIRMA
B1: BAŞAK TRAKTÖR | C1: MATRAH | D1: KDV | E1: G.TOPLAM
B2: HAZİRAN | C2: =[4]HAZİRAN!$C$4+[4]HAZİRAN!$C$5 -> 1861733.3 | D2: =[4]HAZİRAN!$D$4+[4]HAZİRAN!$D$5 -> 329146.67 | E2: =SUM(C2:D2) -> 2190880
B4: ÇALIŞAN HAKEDİŞ ÖDEME TOPLAMI
B5: ='YÜKLENİCİ ARAÇLARI'!C2 -> UFUK KÖYMEN | C5: ='YÜKLENİCİ ARAÇLARI'!H2+'YÜKLENİCİ ARAÇLARI'!H3+'YÜKLENİCİ ARAÇLARI'!H4 -> 34200 | D5: ='YÜKLENİCİ ARAÇLARI'!I2+'YÜKLENİCİ ARAÇLARI'!I3+'YÜKLENİCİ ARAÇLARI'!I4 -> 6840 | E5: =SUM(C5:D5) -> 41040
B6: ='YÜKLENİCİ ARAÇLARI'!C5 -> SAFFET DİN (BÖLGEM TRZ) | C6: ='YÜKLENİCİ ARAÇLARI'!H5 -> 37700 | D6: ='YÜKLENİCİ ARAÇLARI'!I5 -> 7540 | E6: =SUM(C6:D6) -> 45240
B7: ='YÜKLENİCİ ARAÇLARI'!C6 -> YALÇIN DAMAR | C7: ='YÜKLENİCİ ARAÇLARI'!H6+'YÜKLENİCİ ARAÇLARI'!H54+'YÜKLENİCİ ARAÇLARI'!H55+'YÜKLENİCİ ARAÇLARI'!H56 -> 96750 | D7: ='YÜKLENİCİ ARAÇLARI'!I6+'YÜKLENİCİ ARAÇLARI'!I54+'YÜKLENİCİ ARAÇLARI'!I55+'YÜKLENİCİ ARAÇLARI'!I56 -> 19350 | E7: =SUM(C7:D7) -> 116100
B8: ='YÜKLENİCİ ARAÇLARI'!C7 -> MEHMET ANLAŞ | C8: ='YÜKLENİCİ ARAÇLARI'!H7+Tablo5[[#This Row],[TOPLAM]]+'YÜKLENİCİ ARAÇLARI'!H9 -> 35400 | D8: ='YÜKLENİCİ ARAÇLARI'!I7+Tablo5[[#This Row],[0,20%]]+'YÜKLENİCİ ARAÇLARI'!I9 -> 7080 | E8: =SUM(C8:D8) -> 42480
B9: ='YÜKLENİCİ ARAÇLARI'!C10 -> SERKAN AKKOYUN | C9: ='YÜKLENİCİ ARAÇLARI'!H10+'YÜKLENİCİ ARAÇLARI'!H11+'YÜKLENİCİ ARAÇLARI'!H50 -> 24250 | D9: ='YÜKLENİCİ ARAÇLARI'!I10+'YÜKLENİCİ ARAÇLARI'!I11+'YÜKLENİCİ ARAÇLARI'!I50 -> 4850 | E9: ='YÜKLENİCİ ARAÇLARI'!J10+'YÜKLENİCİ ARAÇLARI'!J11+'YÜKLENİCİ ARAÇLARI'!J50 -> 29100
B10: ='YÜKLENİCİ ARAÇLARI'!C12 -> NEVZAT ÖZBAY | C10: ='YÜKLENİCİ ARAÇLARI'!H12 -> 23400 | D10: ='YÜKLENİCİ ARAÇLARI'!I12 -> 0 | E10: =SUM(C10:D10) -> 23400
B11: ='YÜKLENİCİ ARAÇLARI'!C14 -> VEYSEL KARATAŞ | C11: ='YÜKLENİCİ ARAÇLARI'!H14+'YÜKLENİCİ ARAÇLARI'!H15+'YÜKLENİCİ ARAÇLARI'!H32 -> 47550 | D11: ='YÜKLENİCİ ARAÇLARI'!I14+'YÜKLENİCİ ARAÇLARI'!I15+'YÜKLENİCİ ARAÇLARI'!I32 -> 9510 | E11: =SUM(C11:D11) -> 57060
B12: ='YÜKLENİCİ ARAÇLARI'!C16 -> MEHMET SERDAROĞLU | C12: ='YÜKLENİCİ ARAÇLARI'!H16+'YÜKLENİCİ ARAÇLARI'!H17 -> 52250 | D12: ='YÜKLENİCİ ARAÇLARI'!I16+'YÜKLENİCİ ARAÇLARI'!I17 -> 10450 | E12: =SUM(C12:D12) -> 62700
B13: ='YÜKLENİCİ ARAÇLARI'!C18 -> SALİH ÖZTAŞ | C13: ='YÜKLENİCİ ARAÇLARI'!H18 -> 32400 | D13: ='YÜKLENİCİ ARAÇLARI'!I18 -> 0 | E13: =SUM(C13:D13) -> 32400
B14: ='YÜKLENİCİ ARAÇLARI'!C19 -> ELİK TUR(HANİFİ ELİK) | C14: ='YÜKLENİCİ ARAÇLARI'!H19+'YÜKLENİCİ ARAÇLARI'!H20 -> 34000 | D14: ='YÜKLENİCİ ARAÇLARI'!I19+'YÜKLENİCİ ARAÇLARI'!I20 -> 6800 | E14: =SUM(C14:D14) -> 40800
B15: ='YÜKLENİCİ ARAÇLARI'!C21 -> RAMİS GÜMÜŞ | C15: ='YÜKLENİCİ ARAÇLARI'!H21+'YÜKLENİCİ ARAÇLARI'!H41+'YÜKLENİCİ ARAÇLARI'!H42 -> 71050 | D15: ='YÜKLENİCİ ARAÇLARI'!I21+'YÜKLENİCİ ARAÇLARI'!I41+'YÜKLENİCİ ARAÇLARI'!I42 -> 14210 | E15: =SUM(C15:D15) -> 85260
B16: ='YÜKLENİCİ ARAÇLARI'!C24 -> UGUR ERGEZEN | C16: ='YÜKLENİCİ ARAÇLARI'!H24+'YÜKLENİCİ ARAÇLARI'!H25 -> 29700 | D16: ='YÜKLENİCİ ARAÇLARI'!I24+'YÜKLENİCİ ARAÇLARI'!I25 -> 5940 | E16: =SUM(C16:D16) -> 35640
B17: ='YÜKLENİCİ ARAÇLARI'!C22 -> SERHAT TURAN TUR | C17: ='YÜKLENİCİ ARAÇLARI'!H22+'YÜKLENİCİ ARAÇLARI'!H28+'YÜKLENİCİ ARAÇLARI'!H43 -> 36400 | D17: ='YÜKLENİCİ ARAÇLARI'!I22+'YÜKLENİCİ ARAÇLARI'!I28+'YÜKLENİCİ ARAÇLARI'!I43 -> 7280 | E17: =SUM(C17:D17) -> 43680
B18: ='YÜKLENİCİ ARAÇLARI'!C29 -> ERMAN TUR | C18: ='YÜKLENİCİ ARAÇLARI'!H29+'YÜKLENİCİ ARAÇLARI'!H30 -> 23400 | D18: ='YÜKLENİCİ ARAÇLARI'!I29+'YÜKLENİCİ ARAÇLARI'!I30 -> 4680 | E18: =SUM(C18:D18) -> 28080
B19: ='YÜKLENİCİ ARAÇLARI'!C31 -> GÜVEN TUR | C19: ='YÜKLENİCİ ARAÇLARI'!H31 -> 23400 | D19: ='YÜKLENİCİ ARAÇLARI'!I31 -> 4680 | E19: =SUM(C19:D19) -> 28080
B20: ='YÜKLENİCİ ARAÇLARI'!C33 -> KADİR TUNCEL | C20: ='YÜKLENİCİ ARAÇLARI'!H33+'YÜKLENİCİ ARAÇLARI'!H36 -> 46800 | D20: ='YÜKLENİCİ ARAÇLARI'!I33+'YÜKLENİCİ ARAÇLARI'!I36 -> 9360 | E20: =SUM(C20:D20) -> 56160
B21: ='YÜKLENİCİ ARAÇLARI'!C34 -> İBRAHİM AKKUŞ | C21: ='YÜKLENİCİ ARAÇLARI'!H34+'YÜKLENİCİ ARAÇLARI'!H35 -> 49300 | D21: ='YÜKLENİCİ ARAÇLARI'!I34+'YÜKLENİCİ ARAÇLARI'!I35 -> 9860 | E21: =SUM(C21:D21) -> 59160
B22: ='YÜKLENİCİ ARAÇLARI'!C37 -> EMİN-ARZU DİNDAROĞLU | C22: ='YÜKLENİCİ ARAÇLARI'!H37 -> 23400 | D22: ='YÜKLENİCİ ARAÇLARI'!I37 -> 4680 | E22: =SUM(C22:D22) -> 28080
B23: ='YÜKLENİCİ ARAÇLARI'!C38 -> REMZİ/HÜRREM DORUK | C23: ='YÜKLENİCİ ARAÇLARI'!H38 -> 23400 | D23: ='YÜKLENİCİ ARAÇLARI'!I38 -> 0 | E23: =SUM(C23:D23) -> 23400
B24: ='YÜKLENİCİ ARAÇLARI'!C39 -> GÖKHAN IŞIK | C24: ='YÜKLENİCİ ARAÇLARI'!H39+'YÜKLENİCİ ARAÇLARI'!H40+'YÜKLENİCİ ARAÇLARI'!H26+'YÜKLENİCİ ARAÇLARI'!H27 -> 77500 | D24: ='YÜKLENİCİ ARAÇLARI'!I39+'YÜKLENİCİ ARAÇLARI'!I40+'YÜKLENİCİ ARAÇLARI'!I26+'YÜKLENİCİ ARAÇLARI'!I27 -> 15500 | E24: =SUM(C24:D24) -> 93000
B25: ='YÜKLENİCİ ARAÇLARI'!C44 -> RAMAZAN /MERVE YILMAZ | C25: ='YÜKLENİCİ ARAÇLARI'!H44+'YÜKLENİCİ ARAÇLARI'!H23 -> 60500 | D25: ='YÜKLENİCİ ARAÇLARI'!I44+'YÜKLENİCİ ARAÇLARI'!I23 -> 12100 | E25: =SUM(C25:D25) -> 72600
B26: ='YÜKLENİCİ ARAÇLARI'!C45 -> NURİ ŞAHİN ESTUR LIVIN | C26: ='YÜKLENİCİ ARAÇLARI'!H45 -> 27000 | D26: ='YÜKLENİCİ ARAÇLARI'!I45 -> 5400 | E26: =SUM(C26:D26) -> 32400
B27: ='YÜKLENİCİ ARAÇLARI'!C46 -> EMİRCAN KURT | C27: ='YÜKLENİCİ ARAÇLARI'!H46+'YÜKLENİCİ ARAÇLARI'!H48+'YÜKLENİCİ ARAÇLARI'!H49+'YÜKLENİCİ ARAÇLARI'!H51+'YÜKLENİCİ ARAÇLARI'!H53 -> 107800 | D27: ='YÜKLENİCİ ARAÇLARI'!I46+'YÜKLENİCİ ARAÇLARI'!I48+'YÜKLENİCİ ARAÇLARI'!I49+'YÜKLENİCİ ARAÇLARI'!I51+'YÜKLENİCİ ARAÇLARI'!I53 -> 21560 | E27: ='YÜKLENİCİ ARAÇLARI'!J46+'YÜKLENİCİ ARAÇLARI'!J48+'YÜKLENİCİ ARAÇLARI'!J49+'YÜKLENİCİ ARAÇLARI'!J51+'YÜKLENİCİ ARAÇLARI'!J53 -> 129360
B28: ='YÜKLENİCİ ARAÇLARI'!C52 -> Y EMRE OCAK | C28: ='YÜKLENİCİ ARAÇLARI'!H52 -> 9900 | D28: ='YÜKLENİCİ ARAÇLARI'!I52 -> 1980 | E28: =SUM(C28:D28) -> 11880
B29: ='YÜKLENİCİ ARAÇLARI'!C47 -> MUSTAFA ÖZTÜRK | C29: ='YÜKLENİCİ ARAÇLARI'!H47 -> 23400 | D29: ='YÜKLENİCİ ARAÇLARI'!I47 -> 4680 | E29: =SUM(C29:D29) -> 28080
B31: ÇALIŞANA ÖDEME | C31: =SUM(C5:C30) -> 1050850 | D31: =SUM(D5:D30) -> 194330 | E31: =SUM(E5:E30) -> 1245180
B34: ÇALIŞAN ÖDEMEDEN SONRA | C34: MATRAH | D34: KDV | E34: TOPLAM
B35: ÇALIŞAN ÖDEMEDEN SONRA | C35: =C2-C31 -> 810883.33 | D35: =D2-D31 -> 134816.67 | E35: =E2-E31 -> 945700
B38: ASİL TUR ARAÇ KAZANCI | C38: MATRAH | D38: KDV | E38: G.TOPLAM
B39: ='ŞİRKET ARAÇ'!C2 -> 54 S 0562 | C39: ='ŞİRKET ARAÇ'!G2 -> 52500 | D39: ='ŞİRKET ARAÇ'!J2 -> 5250 | E39: =SUM(C39:D39) -> 57750
B40: ='ŞİRKET ARAÇ'!C3 -> 54 S 1173 | C40: ='ŞİRKET ARAÇ'!G3 -> 52500 | D40: ='ŞİRKET ARAÇ'!J3 -> 5250 | E40: =SUM(C40:D40) -> 57750
B41: ='ŞİRKET ARAÇ'!C4 -> 54 S 0857 | C41: ='ŞİRKET ARAÇ'!G4+'ŞİRKET ARAÇ'!G6 -> 91800 | D41: ='ŞİRKET ARAÇ'!J4+'ŞİRKET ARAÇ'!J6 -> 9180 | E41: =SUM(C41:D41) -> 100980
B42: ='ŞİRKET ARAÇ'!C7 -> 54 S 0564 | C42: ='ŞİRKET ARAÇ'!G7 -> 71400 | D42: ='ŞİRKET ARAÇ'!J7 -> 7140 | E42: =SUM(C42:D42) -> 78540
B43: ='ŞİRKET ARAÇ'!C9 -> 54 S 0565 | C43: ='ŞİRKET ARAÇ'!G8+'ŞİRKET ARAÇ'!G9 -> 66300 | D43: ='ŞİRKET ARAÇ'!J9 -> 6630 | E43: =SUM(C43:D43) -> 72930
B44: ='ŞİRKET ARAÇ'!C10 -> 54 S 1194 | C44: ='ŞİRKET ARAÇ'!G10 -> 48750 | D44: ='ŞİRKET ARAÇ'!J10 -> 4875 | E44: =SUM(C44:D44) -> 53625
B45: ='ŞİRKET ARAÇ'!C14 -> 54 S 0257 | C45: ='ŞİRKET ARAÇ'!G14 -> 49400 | D45: ='ŞİRKET ARAÇ'!J14 -> 4940 | E45: =SUM(C45:D45) -> 54340
B46: TOPLAM | C46: =SUM(C39:C45) -> 432650 | D46: =SUM(D39:D45) -> 43265 | E46: =SUM(E39:E45) -> 475915
...

Sheet TOPLAM GELİR VE GİDERLER
A1: FİRMA | B1: PLAKA | C1: BURDA BEBEK | D1: ISILSAN | E1: B-PLAS | F1: ALYAN | G1: VAGON | H1: BAŞAK | I1: ORMAN İŞLETME | J1: ='ŞİRKET ARAÇ'!A159 -> DBE FİRMA | K1: GEDİK KAYNAK
A2: BURDA /3 vrd | B2: 54 S 0571 | C2: ='ŞİRKET ARAÇ'!G129+'ŞİRKET ARAÇ'!G130 -> 108257.5 | L2: =SUM(C2:K2) -> 108257.5
A3: BURDA /MEMUR-KRC | B3: 54 S 0568 | C3: ='ŞİRKET ARAÇ'!G126 -> 0 | L3: =SUM(C3:K3) -> 0
A4: ISILSAN MAKİNA-AYYAN GECE | B4: 54 S 0856 | D4: ='ŞİRKET ARAÇ'!G147+'ŞİRKET ARAÇ'!G152 -> 63650 | F4: ='ŞİRKET ARAÇ'!G81+'ŞİRKET ARAÇ'!G82 -> 31275 | L4: =SUM(C4:K4) -> 94925
A5: ISILSAN MAKİNA | B5: 54 S 0567 | D5: ='ŞİRKET ARAÇ'!G153 -> 72450 | L5: =SUM(C5:K5) -> 72450
A6: ISILSAN MAKİNA | B6: ='ŞİRKET ARAÇ'!C154 -> 54 S 0860 | D6: ='ŞİRKET ARAÇ'!G154 -> 69375 | L6: =SUM(C6:K6) -> 69375
A7: ISILSAN MAKİNA | B7: 54 S 0569 | D7: ='ŞİRKET ARAÇ'!G156 -> 108150 | L7: =SUM(C7:K7) -> 108150
A8: B PLAS 3 VRD/VGON | B8: 54 S 3116 | E8: ='ŞİRKET ARAÇ'!G141+'ŞİRKET ARAÇ'!G142 -> 124100 | G8: ='ŞİRKET ARAÇ'!G30 -> 0 | L8: =SUM(C8:K8) -> 124100
A9: B PLAS KORUCUK | B9: 54 S 0570 | E9: ='ŞİRKET ARAÇ'!G136+'ŞİRKET ARAÇ'!G138 -> 196560 | L9: =SUM(C9:K9) -> 196560
A10: ='ŞİRKET ARAÇ'!A78 -> DDDD | B10: 54 S 0855 | F10: ='ŞİRKET ARAÇ'!G79+'ŞİRKET ARAÇ'!G80 -> 68600 | L10: =SUM(C10:K10) -> 68600
A11: BURDA BEBEK GRŞ ÇIKIŞ | B11: 54 S 0859 | C11: ='ŞİRKET ARAÇ'!G127 -> 75000 | L11: =SUM(C11:K11) -> 75000
A12: ALYAN | B12: 54 S 0858 | F12: ='ŞİRKET ARAÇ'!G89+'ŞİRKET ARAÇ'!G90 -> 53600 | L12: =SUM(C12:K12) -> 53600
A13: ALYAN/3 VRD | B13: 54 S 0560 | L13: =SUM(C13:K13) -> 0
A14: ALYAN/ K.TOPRAK 3 VRD | B14: 54 S 0573 | F14: ='ŞİRKET ARAÇ'!G83+'ŞİRKET ARAÇ'!G84+'ŞİRKET ARAÇ'!G85+'ŞİRKET ARAÇ'!G86 -> 97880 | L14: =SUM(C14:K14) -> 97880
A15: VAGON/BAŞAK | B15: 54 S 1194 | G15: ='ŞİRKET ARAÇ'!G33 -> 46811.25 | H15: ='ŞİRKET ARAÇ'!G10 -> 48750 | L15: =SUM(C15:K15) -> 95561.25
A16: VAGON/BAŞAK | B16: 54 S 0562 | G16: ='ŞİRKET ARAÇ'!G24 -> 95000 | H16: ='ŞİRKET ARAÇ'!G2 -> 52500 | L16: =SUM(C16:K16) -> 147500
A17: VAGON/BAŞAK | B17: 54 S 0565 | G17: ='ŞİRKET ARAÇ'!G26 -> 15603.75 | H17: ='ŞİRKET ARAÇ'!G9 -> 66300 | L17: =SUM(C17:K17) -> 81903.75
A18: VAGON/BAŞAK | B18: 54 S 0564 | G18: ='ŞİRKET ARAÇ'!G27 -> 15603.75 | H18: ='ŞİRKET ARAÇ'!G7 -> 71400 | L18: =SUM(C18:K18) -> 87003.75
A19: VAGON/BAŞAK | B19: 54 S 0857 | G19: ='ŞİRKET ARAÇ'!G32 -> 15603.75 | H19: ='ŞİRKET ARAÇ'!G4 -> 91800 | L19: =SUM(C19:K19) -> 107403.75
A20: VAGON/BAŞAK | B20: 54 S 0257 | G20: ='ŞİRKET ARAÇ'!G29 -> 31207.5 | H20: ='ŞİRKET ARAÇ'!G14 -> 49400 | L20: =SUM(C20:K20) -> 80607.5
A21: VAGON/BAŞAK | B21: 54 S 1773 | G21: ='ŞİRKET ARAÇ'!G31 -> 46811.25 | H21: ='ŞİRKET ARAÇ'!G3 -> 52500 | L21: =SUM(C21:K21) -> 99311.25
A22: VAGON ORMAN | B22: 54 S 2295 | G22: ='ŞİRKET ARAÇ'!G35 -> 15603.75 | I22: ='ŞİRKET ARAÇ'!G74 -> 94050 | L22: =SUM(C22:K22) -> 109653.75
A23: VAGON ORMAN | B23: 54 S 0572 | G23: ='ŞİRKET ARAÇ'!G34 -> 15603.75 | I23: ='ŞİRKET ARAÇ'!G75 -> 94050 | L23: =SUM(C23:K23) -> 109653.75
A24: AQUAKRAFT | B24: 54 S 0563 | J24: ='ŞİRKET ARAÇ'!G162 -> 96600 | L24: =SUM(C24:K24) -> 96600
A25: ='ŞİRKET ARAÇ'!A159 -> DBE FİRMA | B25: 54 S 0566 | J25: ='ŞİRKET ARAÇ'!G160 -> 109200 | L25: =SUM(C25:K25) -> 109200
A26: GEDİK KAYNAK | B26: 54 S 0561 | K26: ='ŞİRKET ARAÇ'!G99 -> 70350 | L26: =SUM(C26:K26) -> 70350
A27: GEDİK KAYNAK VRD | B27: ='ŞİRKET ARAÇ'!C96 -> 54 S 0560 | K27: ='ŞİRKET ARAÇ'!G96+'ŞİRKET ARAÇ'!G97 -> 131040 | L27: =SUM(C27:K27) -> 131040
A28: GEDİK KAYNAK/VAGON | B28: 54 S 2933 | G28: ='ŞİRKET ARAÇ'!G28 -> 15603.75 | K28: ='ŞİRKET ARAÇ'!G107 -> 92700 | L28: =SUM(C28:K28) -> 108303.75
C29: =SUM(C2:C28) -> 183257.5 | D29: =SUM(D2:D28) -> 313625 | E29: =SUM(E2:E28) -> 320660 | F29: =SUM(F2:F28) -> 251355 | G29: =SUM(G2:G28) -> 313452.5 | H29: =SUM(H2:H28) -> 432650 | I29: =SUM(I2:I28) -> 188100 | J29: =SUM(J2:J28) -> 205800 | ... L29: =SUM(L2:L28) -> 2502990
J30: BİNEK ARAÇLAR | L30: ='ŞİRKET ARAÇ'!G64 -> 1030500
J31: ARAÇLAR TOPLAM | L31: =SUM(L29:L30) -> 3533490
A33: FİRMA | B33: PLAKA | C33: TOPLAM KAZANÇ | D33: MAZOT | E33: PERSONEL MAAŞ | F33: SGK | G33: TOPLAM | H33: MEB | I33: GENEL TOPLAM
A34: =A2 -> BURDA /3 vrd | B34: =B2 -> 54 S 0571 | C34: =L2 -> 108257.5 | D34: 23736 | E34: 22500 | F34: 9800 | G34: =C34-D34-E34-F34 -> 52221.5 | I34: =SUM(G34:H34) -> 52221.5
A35: =A11 -> BURDA BEBEK GRŞ ÇIKIŞ | B35: =B11 -> 54 S 0859 | C35: =L11 -> 75000 | D35: 14391.8 | E35: 19000 | F35: 8500 | G35: =C35-D35-E35-F35 -> 33108.2 | H35: ='[1]SAKARYA BÜYÜKŞEHİR'!$G$11 -> 28000 | I35: =SUM(G35:H35) -> 61108.2
A36: =A4 -> ISILSAN MAKİNA-AYYAN GECE | B36: =B4 -> 54 S 0856 | C36: =L4 -> 94925 | D36: 21292.64 | E36: 19000 | F36: 8500 | G36: =C36-D36-E36-F36 -> 46132.36 | H36: ='[1]ADP MEB'!$G$25 -> 20832.5 | I36: =SUM(G36:H36) -> 66964.86
A37: =A5 -> ISILSAN MAKİNA | B37: =B5 -> 54 S 0567 | C37: =L5 -> 72450 | D37: 17112.5 | E37: 20000 | F37: 8500 | G37: =C37-D37-E37-F37 -> 26837.5 | H37: =[1]SERDİVAN!$H$38 -> 19305 | I37: =SUM(G37:H37) -> 46142.5
A38: =A15 -> VAGON/BAŞAK | B38: =B15 -> 54 S 1194 | C38: =L15 -> 95561.25 | D38: 9779 | E38: 19000 | F38: 8500 | G38: =C38-D38-E38-F38 -> 58282.25 | I38: =SUM(G38:H38) -> 58282.25
A39: =A26 -> GEDİK KAYNAK | B39: =B26 -> 54 S 0561 | C39: =L26 -> 70350 | D39: 11075.25 | E39: 19000 | F39: 8500 | G39: =C39-D39-E39-F39 -> 31774.75 | I39: =SUM(G39:H39) -> 31774.75
A40: =A8 -> B PLAS 3 VRD/VGON | B40: =B8 -> 54 S 3116 | C40: =L8 -> 124100 | D40: 20073.95 | E40: 26500 | F40: 9800 | G40: =C40-D40-E40-F40 -> 67726.05 | I40: =SUM(G40:H40) -> 67726.05
A41: =A9 -> B PLAS KORUCUK | B41: 54 S 0570 | C41: =L9 -> 196560 | D41: 41247.68 | E41: 26500 | F41: 9800 | G41: =C41-D41-E41-F41 -> 119012.32 | I41: =SUM(G41:H41) -> 119012.32
...
